Workbook
Name _XP231: #REF!
Name _XP231: #REF!
Name _XP231: #REF!
Name A_impresión_IM: #REF!
Name A_impresión_IM: #REF!
Name A_impresión_IM: #REF!
Name accesorios: #REF!
Name accesorios: #REF!
Name accesorios: #REF!
Name AREA: #REF!
Name AREA: #REF!
Name AREA: #REF!
Name calculo: #REF!
Name calculo: #REF!
Name calculo: #REF!
Name CERECITA: #REF!
Name CODIGO: #REF!
Name CODIGO: #REF!
Name CODIGO: #REF!
Name lista: #REF!
Name lista: #REF!
Name lista: #REF!
Name mama: #REF!
Name mama: #REF!
Name mama: #REF!
Name OK: '[1]APU (SISTEMA_AGUA-VARIOS_PERS)'!#REF!
Name papa: #REF!
Name papa: #REF!
Name papa: #REF!
Name tuberia: #REF!
Name tuberia: #REF!
Name tuberia: #REF!

Sheet PRESUPUESTO
A1: FORMATO PARA PRESUPUESTO
A2: PROYECTO DE CONSTRUCCIÓN DE:
A3: NÚMERO DE TRÁMITE:
A4: FECHA: DD/MM/AA
A5: AREA DE CONSTRUCCIÓN: m²
A6: RUBRO | B6: DETALLE | C6: UNIDAD | D6: CANTIDAD | E6: COSTO UNITARIO (incluido iva) | F6: SUBTOTAL | G6: TOTAL | H6: % | J6: 1 | K6: 1 | L6: TOTAL
J7: AU | K7: M/O | L7: M/O
A9: 1.0 | B9: OBRA GRIS | G9: =SUM(F11:F78) -> 81220.85 | H9: =ROUND(G9/$F$182,4) -> 0.5189
A11: 1.1 | B11: INSTALACIONES PROVISIONALES | G11: =SUM(F11:F15) -> 1405.35 | H11: =ROUND(G11/$F$182,4) -> 0.009
A12: 1.1.01 | B12: Caseta de oficina, bodega y guardiania | C12: m2 | D12: 16 | E12: =IF($A12=0,"",ROUND(J12*$J$6,2)) -> 42.5 | F12: =IF($A12=0,"",ROUND(D12*E12,2)) -> 680 | J12: ='1.1'!$H$56 -> 42.5 | K12: ='1.1'!$H$26 -> 7.58 | L12: =ROUND(K12*D12,2) -> 121.28
A13: 1.1.02 | B13: Instalación eléctrica provisional | C13: Global | D13: 1 | E13: =IF($A13=0,"",ROUND(J13*$J$6,2)) -> 440.6 | F13: =IF($A13=0,"",ROUND(D13*E13,2)) -> 440.6 | J13: ='1.1'!$H$112 -> 440.6 | K13: ='1.1'!$H$82 -> 80.78 | L13: =ROUND(K13*D13,2) -> 80.78
A14: 1.1.03 | B14: Instalación AAPP provisional | C14: Global | D14: 1 | E14: =IF($A14=0,"",ROUND(J14*$J$6,2)) -> 284.75 | F14: =IF($A14=0,"",ROUND(D14*E14,2)) -> 284.75 | J14: ='1.1'!$H$168 -> 284.75 | K14: ='1.1'!$H$138 -> 80.78 | L14: =ROUND(K14*D14,2) -> 80.78
A15: 1.1.04 | B15: Cerramiento de Obra | C15: ml
A16: 1.2 | B16: MANTENIMIENTO DE OBRA | G16: =SUM(F16:F19) -> 2992.64 | H16: =ROUND(G16/$F$182,4) -> 0.0191
A17: 1.2.01 | B17: Limpieza general de la obra | C17: semana | D17: =8*4 -> 32 | E17: =IF($A17=0,"",ROUND(J17*$J$6,2)) -> 51.73 | F17: =IF($A17=0,"",ROUND(D17*E17,2)) -> 1655.36 | J17: ='1.2'!$H$56 -> 51.73 | K17: ='1.2'!$H$26 -> 50.22 | L17: =ROUND(K17*D17,2) -> 1607.04
A18: 1.2.02 | B18: Desalojo de limpieza | C18: viajes | D18: =8*4 -> 32 | E18: =IF($A18=0,"",ROUND(J18*$J$6,2)) -> 41.79 | F18: =IF($A18=0,"",ROUND(D18*E18,2)) -> 1337.28 | J18: ='1.2'!$H$112 -> 41.79 | K18: ='1.2'!$H$82 -> 13.39 | L18: =ROUND(K18*D18,2) -> 428.48
A20: 1.3 | B20: PREPARACION DEL TERRENO | G20: =SUM(F20:F23) -> 523.08 | H20: =ROUND(G20/$F$182,4) -> 0.0033
A21: 1.3.01 | B21: Limpieza del terreno | C21: m2 | D21: 523.09 | E21: =IF($A21=0,"",ROUND(J21*$J$6,2)) -> 0.56 | F21: =IF($A21=0,"",ROUND(D21*E21,2)) -> 292.93 | J21: ='1.3'!$H$56 -> 0.56 | K21: ='1.3'!$H$26 -> 0.54 | L21: =ROUND(K21*D21,2) -> 282.47
A22: 1.3.02 | B22: Replanteo y trazado de cimientos | C22: m2 | D22: 154.46 | E22: =IF($A22=0,"",ROUND(J22*$J$6,2)) -> 1.49 | F22: =IF($A22=0,"",ROUND(D22*E22,2)) -> 230.15 | J22: ='1.3'!$H$168 -> 1.49 | K22: ='1.3'!$H$138 -> 0.71 | L22: =ROUND(K22*D22,2) -> 109.67
A24: 1.4 | B24: MOVIMIENTOS DE TIERRA | G24: =SUM(F24:F27) -> 1991.29 | H24: =ROUND(G24/$F$182,4) -> 0.0127
A25: 1.4.01 | B25: Excavacion | C25: m3 | D25: =58.68*2.5 -> 146.7 | E25: =IF($A25=0,"",ROUND(J25*$J$6,2)) -> 4.04 | F25: =IF($A25=0,"",ROUND(D25*E25,2)) -> 592.67 | J25: ='1.4'!$H$280 -> 4.04 | K25: ='1.4'!$H$194 -> 4.69 | L25: =ROUND(K25*D25,2) -> 688.02
A26: 1.4.02 | B26: Relleno compactado con material importado | C26: m3 | D26: =58.68*2.5*0.9-D33 -> 113.34 | E26: =IF($A26=0,"",ROUND(J26*$J$6,2)) -> 12.34 | F26: =IF($A26=0,"",ROUND(D26*E26,2)) -> 1398.62 | J26: ='1.4'!$H$224 -> 12.34 | K26: ='1.4'!$H$194 -> 4.69 | L26: =ROUND(K26*D26,2) -> 531.56
A28: 1.5 | B28: ESTRUCTURAS DE HORMIGON SIMPLE | G28: =SUM(F28:F31) -> 999.96 | H28: =ROUND(G28/$F$182,4) -> 0.0064
A29: 1.5.01 | B29: Replantillo e= 10cm | C29: m3 | D29: =(58.68+5.76)*0.1 -> 6.444 | E29: =IF($A29=0,"",ROUND(J29*$J$6,2)) -> 113.61 | F29: =IF($A29=0,"",ROUND(D29*E29,2)) -> 732.1 | J29: ='1.5'!$H$56 -> 113.61 | K29: ='1.5'!$H$26 -> 41.74 | L29: =ROUND(K29*D29,2) -> 268.97
A30: 1.5.02 | B30: Muro Ciclopeo | C30: m3 | D30: =(2.1+4.5)*0.25*0.3+1.4 -> 1.895 | E30: =IF($A30=0,"",ROUND(J30*$J$6,2)) -> 141.35 | F30: =IF($A30=0,"",ROUND(D30*E30,2)) -> 267.86 | J30: ='1.5'!$H$112 -> 141.35 | K30: ='1.5'!$H$82 -> 53.92 | L30: =ROUND(K30*D30,2) -> 102.18
A32: 1.6 | B32: ESTRUCTURAS DE HORMIGON ARMADO | G32: =SUM(F32:F45) -> 31688.78 | H32: =ROUND(G32/$F$182,4) -> 0.2025
A33: 1.6.01 | B33: Zapatas y vigas: en cimientos | C33: m3 | D33: =15.94+2.75 -> 18.69 | E33: =IF($A33=0,"",ROUND(J33*$J$6,2)) -> 375.27 | F33: =IF($A33=0,"",ROUND(D33*E33,2)) -> 7013.8 | J33: ='1.6b'!$H$112 -> 375.27 | K33: ='1.6b'!$H$82 -> 98.98 | L33: =ROUND(K33*D33,2) -> 1849.94
A34: 1.6.02 | B34: Riostras | C34: m3 | D34: =0.4+1.12 -> 1.52 | E34: =IF($A34=0,"",ROUND(J34*$J$6,2)) -> 410.9 | F34: =IF($A34=0,"",ROUND(D34*E34,2)) -> 624.57 | J34: ='1.6b'!$H$224 -> 410.9 | K34: ='1.6b'!$H$194 -> 119.93 | L34: =ROUND(K34*D34,2) -> 182.29
A35: 1.6.03 | B35: Columnas cimiento a losa vivienda | C35: m3 | D35: 5.45 | E35: =IF($A35=0,"",ROUND(J35*$J$6,2)) -> 537.64 | F35: =IF($A35=0,"",ROUND(D35*E35,2)) -> 2930.14 | J35: ='1.6b'!$H$280 -> 537.64 | K35: ='1.6b'!$H$250 -> 197.3 | L35: =ROUND(K35*D35,2) -> 1075.29
A36: 1.6.04 | B36: Columnas losa a cubierta | C36: m3 | D36: 3.22 | E36: =IF($A36=0,"",ROUND(J36*$J$6,2)) -> 531.85 | F36: =IF($A36=0,"",ROUND(D36*E36,2)) -> 1712.56 | J36: ='1.6b'!$H$336 -> 531.85 | K36: ='1.6b'!$H$306 -> 184.1 | L36: =ROUND(K36*D36,2) -> 592.8
A37: 1.6.05 | B37: Columnas cimiento a losa garaje | C37: m3 | D37: 0.89 | E37: =IF($A37=0,"",ROUND(J37*$J$6,2)) -> 537.64 | F37: =IF($A37=0,"",ROUND(D37*E37,2)) -> 478.5 | J37: ='1.6b'!$H$280 -> 537.64 | K37: ='1.6b'!$H$250 -> 197.3 | L37: =ROUND(K37*D37,2) -> 175.6
A38: 1.6.06 | B38: Vigas losa entrepiso | C38: m3 | D38: 9.84 | E38: =IF($A38=0,"",ROUND(J38*$J$6,2)) -> 442.28 | F38: =IF($A38=0,"",ROUND(D38*E38,2)) -> 4352.04 | J38: ='1.6b'!$H$448 -> 442.28 | K38: ='1.6b'!$H$418 -> 128.3 | L38: =ROUND(K38*D38,2) -> 1262.47
A39: 1.6.07 | B39: Losa entrepiso e= 25cm | C39: m2 | D39: 130.1 | E39: =IF($A39=0,"",ROUND(J39*$J$6,2)) -> 43.69 | F39: =IF($A39=0,"",ROUND(D39*E39,2)) -> 5684.07 | H39: ='1.6b'!$H$1064*130.22 -> 5689.3118 | J39: ='1.6b'!$H$1064 -> 43.69 | K39: ='1.6b'!$H$586 -> 161.18 | L39: =ROUND(K39*D39,2) -> 20969.52
A40: 1.6.08 | B40: Escaleras de hormigon | C40: m3 | D40: 1.6 | E40: =IF($A40=0,"",ROUND(J40*$J$6,2)) -> 428.47 | F40: =IF($A40=0,"",ROUND(D40*E40,2)) -> 685.55 | J40: ='1.6b'!$H$784 -> 428.47 | K40: ='1.6b'!$H$754 -> 135.66 | L40: =ROUND(K40*D40,2) -> 217.06
A41: 1.6.09 | B41: Vigas de cubierta | C41: m3 | D41: 5.75 | E41: =IF($A41=0,"",ROUND(J41*$J$6,2)) -> 534.58 | F41: =IF($A41=0,"",ROUND(D41*E41,2)) -> 3073.84 | J41: ='1.6b'!$H$504 -> 534.58 | K41: ='1.6b'!$H$474 -> 155.41 | L41: =ROUND(K41*D41,2) -> 893.61
A42: 1.6.10 | B42: Vigas losa de garaje | C42: m3 | D42: 1.9 | E42: =IF($A42=0,"",ROUND(J42*$J$6,2)) -> 442.28 | F42: =IF($A42=0,"",ROUND(D42*E42,2)) -> 840.33 | J42: ='1.6b'!$H$448 -> 442.28 | K42: ='1.6b'!$H$418 -> 128.3 | L42: =ROUND(K42*D42,2) -> 243.77
A43: 1.6.11 | B43: Losa garaje e= 25cm | C43: m2 | D43: 24.91 | E43: =IF($A43=0,"",ROUND(J43*$J$6,2)) -> 43.69 | F43: =IF($A43=0,"",ROUND(D43*E43,2)) -> 1088.32 | J43: ='1.6b'!$H$1064 -> 43.69 | K43: ='1.6b'!$H$586 -> 161.18 | L43: =ROUND(K43*D43,2) -> 4014.99
A44: 1.6.12 | B44: Cisterna | C44: m3 | D44: 6.26 | E44: =IF($A44=0,"",ROUND(J44*$J$6,2)) -> 511.99 | F44: =IF($A44=0,"",ROUND(D44*E44,2)) -> 3205.06 | J44: ='1.6b'!$H$952 -> 511.99 | K44: ='1.6b'!$H$922 -> 155.44 | L44: =ROUND(K44*D44,2) -> 973.05
A46: 1.7 | B46: ESTRUCTURAS METALICAS Y CUBIERTAS | G46: =SUM(F46:F50) -> 9632.67 | H46: =ROUND(G46/$F$182,4) -> 0.0615
A47: 1.7.01 | B47: Estructuras metalicas: de cubierta | C47: kg | D47: =(155*1.05+7.8)*8 -> 1364.4 | E47: =IF($A47=0,"",ROUND(J47*$J$6,2)) -> 2.69 | F47: =IF($A47=0,"",ROUND(D47*E47,2)) -> 3670.24 | J47: ='1.7'!$H$56 -> 2.69 | K47: ='1.7'!$H$26 -> 0.71 | L47: =ROUND(K47*D47,2) -> 968.72
...

Sheet CRONOGRAMA
B1: =PRESUPUESTO!A1 -> FORMATO PARA PRESUPUESTO
B2: =PRESUPUESTO!B3 -> 0 | F2: …. | G2: …. | H2: …. | I2: …. | J2: …. | K2: …. | L2: …. | M2: …. | N2: …. | O2: …. | P2: …. | Q2: …. | R2: …. | S2: …. | T2: …. | U2: …. | V2: …. | W2: …. | X2: …. | Y2: …. | Z2: …. | AA2: …. | AB2: …. | AC2: …. | AD2: …. | AE2: …. | AF2: …. | AG2: …. | AH2: …. | AI2: …. | AJ2: …. | AK2: ….
B3: CRONOGRAMA VALORADO
F4: 2024
F5: Abril | J5: Mayo | N5: Junio | R5: Julio | V5: Agosto | Z5: Septiembre | AD5: Octubre | AH5: Noviembre
C6: RUBROS | F6: MES 1 | J6: MES 2 | N6: MES 3 | R6: MES 4 | V6: MES 5 | Z6: MES 6 | AD6: MES 7 | AH6: MES 8
F7: 1 | G7: 2 | H7: 3 | I7: 4 | J7: 1 | K7: 2 | L7: 3 | M7: 4 | N7: 1 | O7: 2 | P7: 3 | Q7: 4 | R7: 1 | S7: 2 | T7: 3 | U7: 4 | V7: 1 | W7: 2 | X7: 3 | Y7: 4 | Z7: 1 | AA7: 2 | AB7: 3 | AC7: 4 | AD7: 1 | AE7: 2 | AF7: 3 | AG7: 4 | AH7: 1 | AI7: 2 | AJ7: 3 | AK7: 4
B8: 1.1 | C8: INSTALACIONES PROVISIONALES | D8: =VLOOKUP(C8,PRESUPUESTO!$B$10:$G$180,6,FALSE) -> 1405.35 | E8: 1 | F8: =ROUND($D8/$E8,2) -> 1405.35 | AM8: =SUM(F8:AL8) -> 1405.35 | AO8: =+D8-AM8 -> 0
B9: 1.2 | C9: MANTENIMIENTO DE OBRA | D9: =VLOOKUP(C9,PRESUPUESTO!$B$10:$G$180,6,FALSE) -> 2992.64 | E9: 32 | F9: =ROUND($D9/$E9,2) -> 93.52 | G9: =ROUND($D9/$E9,2) -> 93.52 | H9: =ROUND($D9/$E9,2) -> 93.52 | I9: =ROUND($D9/$E9,2) -> 93.52 | J9: =ROUND($D9/$E9,2) -> 93.52 | K9: =ROUND($D9/$E9,2) -> 93.52 | L9: =ROUND($D9/$E9,2) -> 93.52 | M9: =ROUND($D9/$E9,2) -> 93.52 | ... AK9: =ROUND($D9/$E9,2) -> 93.52 | AM9: =SUM(F9:AL9) -> 2992.64 | AO9: =+D9-AM9 -> 0
B10: 1.3 | C10: PREPARACION DEL TERRENO | D10: =VLOOKUP(C10,PRESUPUESTO!$B$10:$G$180,6,FALSE) -> 523.08 | E10: 1 | F10: =ROUND($D10/$E10,2) -> 523.08 | AM10: =SUM(F10:AL10) -> 523.08 | AO10: =+D10-AM10 -> 0
B11: 1.4 | C11: MOVIMIENTOS DE TIERRA | D11: =VLOOKUP(C11,PRESUPUESTO!$B$10:$G$180,6,FALSE) -> 1991.29 | E11: 2 | F11: =ROUND($D11/$E11,2) -> 995.65 | G11: =ROUND($D11/$E11,2) -> 995.65 | AM11: =SUM(F11:AL11) -> 1991.3 | AO11: =+D11-AM11 -> -0.01
C12: Excavación para cimientos (Manual) | AM12: =SUM(F12:AL12) -> 0 | AO12: =+D12-AM12 -> 0
C13: Relleno compactado con material importado | AM13: =SUM(F13:AL13) -> 0 | AO13: =+D13-AM13 -> 0
C14: Desalojo | AM14: =SUM(F14:AL14) -> 0 | AO14: =+D14-AM14 -> 0
B15: 1.5 | C15: ESTRUCTURAS DE HORMIGON SIMPLE | D15: =VLOOKUP(C15,PRESUPUESTO!$B$10:$G$180,6,FALSE) -> 999.96 | E15: 4 | G15: =ROUND($D15/$E15,2) -> 249.99 | H15: =ROUND($D15/$E15,2) -> 249.99 | I15: =ROUND($D15/$E15,2) -> 249.99 | J15: =ROUND($D15/$E15,2) -> 249.99 | AM15: =SUM(F15:AL15) -> 999.96 | AO15: =+D15-AM15 -> 0
C16: Replantillo | AM16: =SUM(F16:AL16) -> 0 | AO16: =+D16-AM16 -> 0
C17: Muro Ciclopeo | AM17: =SUM(F17:AL17) -> 0 | AO17: =+D17-AM17 -> 0
B18: 1.6 | C18: ESTRUCTURAS DE HORMIGON ARMADO | D18: =VLOOKUP(C18,PRESUPUESTO!$B$10:$G$180,6,FALSE) -> 31688.78 | E18: 12 | I18: =ROUND($D18/$E18,2) -> 2640.73 | J18: =ROUND($D18/$E18,2) -> 2640.73 | K18: =ROUND($D18/$E18,2) -> 2640.73 | L18: =ROUND($D18/$E18,2) -> 2640.73 | M18: =ROUND($D18/$E18,2) -> 2640.73 | N18: =ROUND($D18/$E18,2) -> 2640.73 | O18: =ROUND($D18/$E18,2) -> 2640.73 | P18: =ROUND($D18/$E18,2) -> 2640.73 | ... T18: =ROUND($D18/$E18,2) -> 2640.73 | AM18: =SUM(F18:AL18) -> 31688.76 | AO18: =+D18-AM18 -> 0.02
C19: Zapata y viga de cimentacion, Riostras | AM19: =SUM(F19:AL19) -> 0 | AO19: =+D19-AM19 -> 0
C20: Columnas: cimiento a losa; losa a cubierta, Garaje | AM20: =SUM(F20:AL20) -> 0 | AO20: =+D20-AM20 -> 0
C21: Hormigon armado en Losa e= 25cm,Macizos y Vigas de losa, Escalera | AM21: =SUM(F21:AL21) -> 0 | AO21: =+D21-AM21 -> 0
C22: Cisterna | AM22: =SUM(F22:AL22) -> 0 | AO22: =+D22-AM22 -> 0
C23: Vigas de cubierta; Hormigon armado en Losa garaje | AM23: =SUM(F23:AL23) -> 0 | AO23: =+D23-AM23 -> 0
B24: 1.7 | C24: ESTRUCTURAS METALICAS Y CUBIERTAS | D24: =VLOOKUP(C24,PRESUPUESTO!$B$10:$G$180,6,FALSE) -> 9632.67 | E24: 10 | M24: =ROUND($D24/$E24,2) -> 963.27 | N24: =ROUND($D24/$E24,2) -> 963.27 | O24: =ROUND($D24/$E24,2) -> 963.27 | P24: =ROUND($D24/$E24,2) -> 963.27 | Q24: =ROUND($D24/$E24,2) -> 963.27 | R24: =ROUND($D24/$E24,2) -> 963.27 | S24: =ROUND($D24/$E24,2) -> 963.27 | T24: =ROUND($D24/$E24,2) -> 963.27 | ... V24: =ROUND($D24/$E24,2) -> 963.27 | AM24: =SUM(F24:AL24) -> 9632.7 | AO24: =+D24-AM24 -> -0.03
C25: Estructuras metalicas: de cubierta | AM25: =SUM(F25:AL25) -> 0 | AO25: =+D25-AM25 -> 0
C26: Cubierta Eternit | AM26: =SUM(F26:AL26) -> 0 | AO26: =+D26-AM26 -> 0
C27: Tejas sobre cubierta | AM27: =SUM(F27:AL27) -> 0 | AO27: =+D27-AM27 -> 0
B28: 1.8 | C28: CONTRAPISOS | D28: =VLOOKUP(C28,PRESUPUESTO!$B$10:$G$180,6,FALSE) -> 1403.06 | E28: 2 | K28: =ROUND($D28/$E28,2) -> 701.53 | L28: =ROUND($D28/$E28,2) -> 701.53 | AM28: =SUM(F28:AL28) -> 1403.06 | AO28: =+D28-AM28 -> 0
B29: 1.9 | C29: ALBAÑILERIA | E29: 12 | N29: =ROUND($D29/$E29,2) -> 0 | O29: =ROUND($D29/$E29,2) -> 0 | P29: =ROUND($D29/$E29,2) -> 0 | Q29: =ROUND($D29/$E29,2) -> 0 | R29: =ROUND($D29/$E29,2) -> 0 | S29: =ROUND($D29/$E29,2) -> 0 | T29: =ROUND($D29/$E29,2) -> 0 | U29: =ROUND($D29/$E29,2) -> 0 | ... Y29: =ROUND($D29/$E29,2) -> 0 | AM29: =SUM(F29:AL29) -> 0 | AO29: =+D29-AM29 -> 0
C30: Mamposterias y Viguetas | AM30: =SUM(F30:AL30) -> 0 | AO30: =+D30-AM30 -> 0
C31: Enlucidos | AM31: =SUM(F31:AL31) -> 0 | AO31: =+D31-AM31 -> 0
C32: Mesones, muros de tina, Cajas | AM32: =SUM(F32:AL32) -> 0 | AO32: =+D32-AM32 -> 0
C33: Impermeabilizaciones | AM33: =SUM(F33:AL33) -> 0 | AO33: =+D33-AM33 -> 0
B34: 2.1 | C34: REVESTIMIENTOS Y ACABADOS | D34: =VLOOKUP(C34,PRESUPUESTO!$B$10:$G$180,6,FALSE) -> #N/A | E34: 14 | V34: =ROUND($D34/$E34,2) -> #N/A | W34: =ROUND($D34/$E34,2) -> #N/A | X34: =ROUND($D34/$E34,2) -> #N/A | Y34: =ROUND($D34/$E34,2) -> #N/A | Z34: =ROUND($D34/$E34,2) -> #N/A | AA34: =ROUND($D34/$E34,2) -> #N/A | AB34: =ROUND($D34/$E34,2) -> #N/A | AC34: =ROUND($D34/$E34,2) -> #N/A | ... AI34: =ROUND($D34/$E34,2) -> #N/A | AM34: =SUM(F34:AL34) -> #N/A | AO34: =+D34-AM34 -> #N/A
C35: Ceramicas y porcelanatos en pisos | AM35: =SUM(F35:AL35) -> 0 | AO35: =+D35-AM35 -> 0
C36: Revestimiento de mesones y escalera | AM36: =SUM(F36:AL36) -> 0 | AO36: =+D36-AM36 -> 0
C37: Pintura interior y exterior | AM37: =SUM(F37:AL37) -> 0 | AO37: =+D37-AM37 -> 0
B38: 2.2 | C38: CIELOS RASOS | D38: =VLOOKUP(C38,PRESUPUESTO!$B$10:$G$180,6,FALSE) -> 5930.35 | E38: 7 | AA38: =ROUND($D38/$E38,2) -> 847.19 | AB38: =ROUND($D38/$E38,2) -> 847.19 | AC38: =ROUND($D38/$E38,2) -> 847.19 | AD38: =ROUND($D38/$E38,2) -> 847.19 | AE38: =ROUND($D38/$E38,2) -> 847.19 | AF38: =ROUND($D38/$E38,2) -> 847.19 | AG38: =ROUND($D38/$E38,2) -> 847.19 | AM38: =SUM(F38:AL38) -> 5930.33 | AO38: =+D38-AM38 -> 0.02
B39: 2.3 | C39: CARPINTERIA: ALUMINIO / VIDRIO | D39: =VLOOKUP(C39,PRESUPUESTO!$B$10:$G$180,6,FALSE) -> #N/A | E39: 7 | AC39: =ROUND($D39/$E39,2) -> #N/A | AD39: =ROUND($D39/$E39,2) -> #N/A | AE39: =ROUND($D39/$E39,2) -> #N/A | AF39: =ROUND($D39/$E39,2) -> #N/A | AG39: =ROUND($D39/$E39,2) -> #N/A | AH39: =ROUND($D39/$E39,2) -> #N/A | AI39: =ROUND($D39/$E39,2) -> #N/A | AM39: =SUM(F39:AL39) -> #N/A | AO39: =+D39-AM39 -> #N/A
B40: 2.4 | C40: CARPINTERIA: MADERA | D40: =VLOOKUP(C40,PRESUPUESTO!$B$10:$G$180,6,FALSE) -> 9203.31 | E40: 6 | AF40: =ROUND($D40/$E40,2) -> 1533.89 | AG40: =ROUND($D40/$E40,2) -> 1533.89 | AH40: =ROUND($D40/$E40,2) -> 1533.89 | AI40: =ROUND($D40/$E40,2) -> 1533.89 | AJ40: =ROUND($D40/$E40,2) -> 1533.89 | AK40: =ROUND($D40/$E40,2) -> 1533.89 | AM40: =SUM(F40:AL40) -> 9203.34 | AO40: =+D40-AM40 -> -0.03
...

Sheet CALCULO 
A1: AREAS
A2: TOTAL | B2: =SUM(C4:C63) -> 59.18 | C2: M2
A4: REPLANTEO | C4: =ROUND(E4*G4,2) -> 0 | E4: 1 | F4: M2 | G4: =SUM(H4:AP4) -> 0
A5: PISO 1 | C5: =ROUND(E5*G5,2) -> 0 | E5: 1 | F5: ML | G5: =SUM(H5:AP5) -> 0
A6: PISO 2 | C6: =ROUND(E6*G6,2) -> 0 | E6: 1 | F6: ML | G6: =SUM(H6:AP6) -> 0
G7: =SUM(H7:AP7) -> 0
A8: EXCAVACION MANUAL | G8: =SUM(H8:AG8) -> 0
A9: TOTAL | B9: =SUM(C11:C15)-B10 -> 0 | C9: M3 | G9: =SUM(H9:AG9) -> 0
G10: =SUM(H10:AG10) -> 0
A11: PLINTOS | C11: =ROUND(E11*G11,2) -> 0 | E11: 0.8 | F11: M2 | G11: =SUM(H11:AG11) -> 0
A12: RIOSTRAS | C12: =ROUND(E12*G12,2) -> 0 | E12: =0.8*0.7 -> 0.56 | F12: ML | G12: =SUM(H12:AG12) -> 0
A13: PLINTOS ESCALERA | C13: =ROUND(E13*G13,2) -> 0 | E13: 0.8 | F13: M2 | G13: =SUM(H13:AG13) -> 0
A14: RIOSTRAS ESCALERA | C14: =ROUND(E14*G14,2) -> 0 | E14: 0.8 | F14: M2 | G14: =SUM(H14:AG14) -> 0
G15: =SUM(H15:AG15) -> 0
A16: REPLANTILLO | G16: =SUM(H16:AG16) -> 0
A17: TOTAL | B17: =SUM(C19:C20) -> 5.81 | C17: M3 | G17: =SUM(H17:AG17) -> 0
G18: =SUM(H18:AG18) -> 0
A19: REPLANTILLO EN PLINTOS | C19: =ROUND(E19*G19,2) -> 3.95 | E19: 0.05 | F19: M2 | G19: =SUM(H19:AG19) -> 78.96 | H19: 211.75 | I19: 3.27 | J19: -11 | K19: -10.8 | L19: -9.9 | M19: -12.75 | N19: -1.3 | O19: -7.49 | P19: -9.36 | Q19: -8.58 | R19: -10.12 | S19: -2.2 | T19: -11.8 | U19: -14.04 | V19: -12.87 | W19: -13.85
A20: REPLANTILLO EN PLINTOS | C20: =ROUND(E20*G20,2) -> 1.86 | E20: 0.05 | F20: M3 | G20: =SUM(H20:AG20) -> 37.23 | H20: =0.9*0.9*4 -> 3.24 | I20: =1.1*1.1*5 -> 6.05 | J20: =1.4*1.4*8 -> 15.68 | K20: =1.7*1.7*2 -> 5.78 | L20: =1.8*1.8*2 -> 6.48
A21: REPLANTILLO EN PARQUEOS | C21: =ROUND(E21*G21,2) -> 0.16 | E21: 0.05 | F21: M3 | G21: =SUM(H21:AG21) -> 3.23 | H21: =0.9*0.9 -> 0.81 | I21: =1.1*1.1*2 -> 2.42
A22: cimientos | G22: =SUM(H22:AG22) -> 0
A23: TOTAL | B23: =SUM(C25:C33) -> 5.27 | C23: M3 | D23: =7.65/2.05 -> 3.7317073 | E23: =25.37/8.9 -> 2.8505618 | G23: =SUM(H23:AG23) -> 0
G24: =SUM(H24:AG24) -> 0
A25: plintos | B25: =SUM(C25:C29) -> 2.75 | C25: =ROUND(E25*G25,2) -> 2.75 | E25: =(0.44+0.8)*0.1*0.5+0.15 -> 0.212 | F25: M2 | G25: =SUM(H25:AG25) -> 12.96 | H25: =1.8*1.8 -> 3.24 | I25: =1.8*1.8 -> 3.24 | J25: =1.8*1.8 -> 3.24 | K25: =1.8*1.8 -> 3.24
C26: =ROUND(E26*G26,2) -> 0 | E26: =(0.44+1)*0.1*0.5+0.15 -> 0.222 | F26: M2 | G26: =SUM(H26:AG26) -> 0
C27: =ROUND(E27*G27,2) -> 0 | E27: =(0.44+1.3)*0.1*0.5+0.15 -> 0.237 | G27: =SUM(H27:AG27) -> 0
C28: =ROUND(E28*G28,2) -> 0 | E28: =(0.44+1.6)*0.1*0.5+0.15 -> 0.252 | G28: =SUM(H28:AG28) -> 0
C29: =ROUND(E29*G29,2) -> 0 | E29: =(0.44+1.7)*0.1*0.5+0.15 -> 0.257 | G29: =SUM(H29:AG29) -> 0
A30: riostras | C30: =ROUND(E30*G30,2) -> 1.12 | E30: =0.2*0.3 -> 0.06 | F30: M2 | G30: =SUM(H30:AG30) -> 18.7 | H30: 5.2 | I30: 5.2 | J30: 3.6 | K30: 4.7
A31: ciclopeo | C31: =ROUND(E31*G31,2) -> 1.4 | E31: =(0.2+0.3)*0.3*0.5 -> 0.075 | F31: M2 | G31: =SUM(H31:AG31) -> 18.7 | H31: 5.2 | I31: 5.2 | J31: 3.6 | K31: 4.7
A32: plintos parqueos | C32: =ROUND(E32*G32,2) -> 0 | E32: =(0.44+1)*0.1*0.5+0.15 -> 0.222 | F32: M2 | G32: =SUM(H32:AG32) -> 0
A33: riostras parqueo | C33: =ROUND(E33*G33,2) -> 0 | E33: =0.2*0.2 -> 0.04 | F33: M2 | G33: =SUM(H33:AG33) -> 0
G34: =SUM(H34:AG34) -> 0
A35: cimientos | G35: =SUM(H35:AG35) -> 0
A36: TOTAL | B36: =SUM(C38:C39) -> 15.94 | C36: M3 | G36: =SUM(H36:AG36) -> 0
G37: =SUM(H37:AG37) -> 0
A38: zapatas | C38: =ROUND(E38*G38,2) -> 10.56 | E38: 0.18 | F38: M2 | G38: =SUM(H38:AG38) -> 58.68 | H38: 8.9 | I38: 8.56 | J38: 2.39 | K38: 6.85 | L38: 5.1 | M38: 1.69 | N38: 2.05 | O38: 4.2 | P38: 2.81 | Q38: 2.89 | R38: 2.66 | S38: 1.4 | T38: 0.92 | U38: 0.98 | V38: 1.85 | W38: 1.42 | X38: 1 | Y38: 1.16 | Z38: 1.85
A39: vigas | C39: =ROUND(E39*G39,2) -> 5.38 | E39: =0.2*0.25 -> 0.05 | F39: M2 | G39: =SUM(H39:AG39) -> 107.62 | H39: 14.51 | I39: 14.17 | J39: 6.32 | K39: 8.5 | L39: 8.7 | M39: 4.63 | N39: 4.5 | O39: 8.2 | P39: 4.5 | Q39: 4.73 | R39: 4.3 | S39: 3.2 | T39: 2.17 | U39: 2.54 | V39: 4.2 | W39: 3.24 | X39: 2.35 | Y39: 2.81 | Z39: 4.05
A40: riostras | C40: =ROUND(E40*G40,2) -> 0.4 | E40: =0.2*0.3 -> 0.06 | F40: M2 | G40: =SUM(H40:AG40) -> 6.6 | H40: 4.5 | I40: 2.1
A41: ciclopeo | C41: =ROUND(E41*G41,2) -> 0.5 | E41: =(0.2+0.3)*0.3*0.5 -> 0.075 | F41: M2 | G41: =SUM(H41:AG41) -> 6.6 | H41: 4.5 | I41: 2.1
...

Sheet 1.1
B1: NOMBRE DEL PROPONENTE: | D1: ESPOL | H1: FORM. #3 | L1: =A5 -> 1 | M1: =C6 -> Caseta de oficina, bodega y guardiania | N1: =H5 -> m2 | O1: =H56 -> 42.5
B2: OBRA: | C2: =PRESUPUESTO!$B$3 -> 0 | G2: HOJA | I2: de
C3: =PRESUPUESTO!$B$4 -> 0
B4: ANALISIS DE PRECIOS UNITARIOS
A5: 1 | B5: RUBRO | C5: 1.1.1 | G5: UNIDAD: | H5: m2
B6: DETALLE | C6: Caseta de oficina, bodega y guardiania
B8: EQUIPOS
B9: DESCRIPCION | D9: CANTIDAD A | E9: TARIFA B | F9: COSTO HORA C= A*B | G9: RENDIMIENTO | H9: COSTO D=C*R
A10: 19015 | B10: =IF($A10=0,"",VLOOKUP($A10,'BASE EQUIPO'!$A:$D,2)) -> HERRAMIENTA MENOR | D10: 1 | E10: =IF($A10=0,"",VLOOKUP($A10,'BASE EQUIPO'!$A:$D,4)*H26) -> 0.2274 | F10: =IF($A10=0,"",ROUND(D10*E10,2)) -> 0.23 | G10: 1 | H10: =IF($A10=0,"",ROUND(G10*F10,2)) -> 0.23
B11: =IF($A11=0,"",VLOOKUP($A11,'BASE EQUIPO'!$A:$D,2)) | E11: =IF($A11=0,"",VLOOKUP($A11,'BASE EQUIPO'!$A:$D,4)) | F11: =IF($A11=0,"",ROUND(D11*E11,2)) | H11: =IF($A11=0,"",ROUND(G11*F11,2))
B12: =IF($A12=0,"",VLOOKUP($A12,'BASE EQUIPO'!$A:$D,2)) | E12: =IF($A12=0,"",VLOOKUP($A12,'BASE EQUIPO'!$A:$D,4)) | F12: =IF($A12=0,"",ROUND(D12*E12,2)) | H12: =IF($A12=0,"",ROUND(G12*F12,2))
B13: =IF($A13=0,"",VLOOKUP($A13,'BASE EQUIPO'!$A:$D,2)) | E13: =IF($A13=0,"",VLOOKUP($A13,'BASE EQUIPO'!$A:$D,4)) | F13: =IF($A13=0,"",ROUND(D13*E13,2)) | H13: =IF($A13=0,"",ROUND(G13*F13,2))
B14: =IF($A14=0,"",VLOOKUP($A14,'BASE EQUIPO'!$A:$D,2)) | E14: =IF($A14=0,"",VLOOKUP($A14,'BASE EQUIPO'!$A:$D,4)) | F14: =IF($A14=0,"",ROUND(D14*E14,2)) | H14: =IF($A14=0,"",ROUND(G14*F14,2))
B15: =IF($A15=0,"",VLOOKUP($A15,'BASE EQUIPO'!$A:$D,2)) | E15: =IF($A15=0,"",VLOOKUP($A15,'BASE EQUIPO'!$A:$D,4)) | F15: =IF($A15=0,"",ROUND(D15*E15,2)) | H15: =IF($A15=0,"",ROUND(G15*F15,2))
B16: SUBTOTAL M | H16: =ROUND(SUM(H9:H15),2) -> 0.23
B17: MANO DE OBRA
B18: DESCRIPCION (CATEG) | D18: CANTIDAD A | E18: JORNAL/HR B | F18: COSTO HORA C= A*B | G18: RENDIMIENTO | H18: COSTO D=C*R
A19: 20001 | B19: =IF($A19=0,"",VLOOKUP($A19,'BASE M-OBRA'!$A:$D,2)) -> MAESTRO | D19: 1 | E19: =IF($A19=0,"",VLOOKUP($A19,'BASE M-OBRA'!$A:$D,4)) -> 3.02 | F19: =IF($A19=0,"",ROUND(D19*E19,2)) -> 3.02 | G19: =IF($A19=0,"",ROUND(H19/F19,2)) -> 0.42 | H19: =IF($A19=0,"",ROUND(SUM(H20:H25)*'BASE M-OBRA'!$D$23,2)) -> 1.26
A20: 20004 | B20: =IF($A20=0,"",VLOOKUP($A20,'BASE M-OBRA'!$A:$D,2)) -> CARPINTERO | D20: 2 | E20: =IF($A20=0,"",VLOOKUP($A20,'BASE M-OBRA'!$A:$D,4)) -> 2.82 | F20: =IF($A20=0,"",ROUND(D20*E20,2)) -> 5.64 | G20: 0.75 | H20: =IF($A20=0,"",ROUND(G20*F20,2)) -> 4.23
A21: 20002 | B21: =IF($A21=0,"",VLOOKUP($A21,'BASE M-OBRA'!$A:$D,2)) -> PEON | D21: 1 | E21: =IF($A21=0,"",VLOOKUP($A21,'BASE M-OBRA'!$A:$D,4)) -> 2.79 | F21: =IF($A21=0,"",ROUND(D21*E21,2)) -> 2.79 | G21: =+G20 -> 0.75 | H21: =IF($A21=0,"",ROUND(G21*F21,2)) -> 2.09
B22: =IF($A22=0,"",VLOOKUP($A22,'BASE M-OBRA'!$A:$D,2)) | E22: =IF($A22=0,"",VLOOKUP($A22,'BASE M-OBRA'!$A:$D,4)) | F22: =IF($A22=0,"",ROUND(D22*E22,2)) | H22: =IF($A22=0,"",ROUND(G22*F22,2))
B23: =IF($A23=0,"",VLOOKUP($A23,'BASE M-OBRA'!$A:$D,2)) | E23: =IF($A23=0,"",VLOOKUP($A23,'BASE M-OBRA'!$A:$D,4)) | F23: =IF($A23=0,"",ROUND(D23*E23,2)) | H23: =IF($A23=0,"",ROUND(G23*F23,2))
B24: =IF($A24=0,"",VLOOKUP($A24,'BASE M-OBRA'!$A:$D,2)) | E24: =IF($A24=0,"",VLOOKUP($A24,'BASE M-OBRA'!$A:$D,4)) | F24: =IF($A24=0,"",ROUND(D24*E24,2)) | H24: =IF($A24=0,"",ROUND(G24*F24,2))
B25: =IF($A25=0,"",VLOOKUP($A25,'BASE M-OBRA'!$A:$D,2)) | E25: =IF($A25=0,"",VLOOKUP($A25,'BASE M-OBRA'!$A:$D,4)) | F25: =IF($A25=0,"",ROUND(D25*E25,2)) | H25: =IF($A25=0,"",ROUND(G25*F25,2))
B26: SUBTOTAL N | H26: =ROUND(SUM(H18:H25),2) -> 7.58
B27: MATERIALES
B28: DESCRIPCION | E28: UNIDAD | F28: CANTIDAD A | G28: UNITARIO B | H28: COSTO C=A*B
A29: 11008 | B29: =IF($A29=0,"",VLOOKUP($A29,'BASE MATERIAL'!$A:$D,2)) -> TABLA | E29: =IF($A29=0,"",VLOOKUP($A29,'BASE MATERIAL'!$A:$D,3)) -> U | F29: 3 | G29: =IF($A29=0,"",VLOOKUP($A29,'BASE MATERIAL'!$A:$D,4)) -> 3.5 | H29: =IF($A29=0,"",ROUND(F29*G29,2)) -> 10.5
A30: 11009 | B30: =IF($A30=0,"",VLOOKUP($A30,'BASE MATERIAL'!$A:$D,2)) -> CUARTON | E30: =IF($A30=0,"",VLOOKUP($A30,'BASE MATERIAL'!$A:$D,3)) -> U | F30: 1.15 | G30: =IF($A30=0,"",VLOOKUP($A30,'BASE MATERIAL'!$A:$D,4)) -> 2.42 | H30: =IF($A30=0,"",ROUND(F30*G30,2)) -> 2.78
A31: 11010 | B31: =IF($A31=0,"",VLOOKUP($A31,'BASE MATERIAL'!$A:$D,2)) -> TIRA | E31: =IF($A31=0,"",VLOOKUP($A31,'BASE MATERIAL'!$A:$D,3)) -> U | F31: 0.6 | G31: =IF($A31=0,"",VLOOKUP($A31,'BASE MATERIAL'!$A:$D,4)) -> 1.5 | H31: =IF($A31=0,"",ROUND(F31*G31,2)) -> 0.9
A32: 11007 | B32: =IF($A32=0,"",VLOOKUP($A32,'BASE MATERIAL'!$A:$D,2)) -> CLAVO 2 1/2" | E32: =IF($A32=0,"",VLOOKUP($A32,'BASE MATERIAL'!$A:$D,3)) -> KG | F32: 0.12 | G32: =IF($A32=0,"",VLOOKUP($A32,'BASE MATERIAL'!$A:$D,4)) -> 2.652 | H32: =IF($A32=0,"",ROUND(F32*G32,2)) -> 0.32
A33: 12012 | B33: =IF($A33=0,"",VLOOKUP($A33,'BASE MATERIAL'!$A:$D,2)) -> PLANCHA DE ZINC 8' REFORZADA | E33: =IF($A33=0,"",VLOOKUP($A33,'BASE MATERIAL'!$A:$D,3)) -> U | F33: 0.75 | G33: =IF($A33=0,"",VLOOKUP($A33,'BASE MATERIAL'!$A:$D,4)) -> 8.53 | H33: =IF($A33=0,"",ROUND(F33*G33,2)) -> 6.4
A34: 10016 | B34: =IF($A34=0,"",VLOOKUP($A34,'BASE MATERIAL'!$A:$D,2)) -> BISAGRA CROMADA | E34: =IF($A34=0,"",VLOOKUP($A34,'BASE MATERIAL'!$A:$D,3)) -> U | F34: 0.1 | G34: =IF($A34=0,"",VLOOKUP($A34,'BASE MATERIAL'!$A:$D,4)) -> 1.2 | H34: =IF($A34=0,"",ROUND(F34*G34,2)) -> 0.12
A35: 11016 | B35: =IF($A35=0,"",VLOOKUP($A35,'BASE MATERIAL'!$A:$D,2)) -> ARGOLLAS | E35: =IF($A35=0,"",VLOOKUP($A35,'BASE MATERIAL'!$A:$D,3)) -> U | F35: 0.08 | G35: =IF($A35=0,"",VLOOKUP($A35,'BASE MATERIAL'!$A:$D,4)) -> 0.77 | H35: =IF($A35=0,"",ROUND(F35*G35,2)) -> 0.06
A36: 11015 | B36: =IF($A36=0,"",VLOOKUP($A36,'BASE MATERIAL'!$A:$D,2)) -> CANDADO | E36: =IF($A36=0,"",VLOOKUP($A36,'BASE MATERIAL'!$A:$D,3)) -> U | F36: 0.08 | G36: =IF($A36=0,"",VLOOKUP($A36,'BASE MATERIAL'!$A:$D,4)) -> 6.39 | H36: =IF($A36=0,"",ROUND(F36*G36,2)) -> 0.51
A37: 11017 | B37: =IF($A37=0,"",VLOOKUP($A37,'BASE MATERIAL'!$A:$D,2)) -> PLYWOOD CASETA 9MM | E37: =IF($A37=0,"",VLOOKUP($A37,'BASE MATERIAL'!$A:$D,3)) -> U | F37: 0.5 | G37: =IF($A37=0,"",VLOOKUP($A37,'BASE MATERIAL'!$A:$D,4)) -> 24.17 | H37: =IF($A37=0,"",ROUND(F37*G37,2)) -> 12.09
B38: =IF($A38=0,"",VLOOKUP($A38,'BASE MATERIAL'!$A:$D,2)) | E38: =IF($A38=0,"",VLOOKUP($A38,'BASE MATERIAL'!$A:$D,3)) | G38: =IF($A38=0,"",VLOOKUP($A38,'BASE MATERIAL'!$A:$D,4)) | H38: =IF($A38=0,"",ROUND(F38*G38,2))
B39: =IF($A39=0,"",VLOOKUP($A39,'BASE MATERIAL'!$A:$D,2)) | E39: =IF($A39=0,"",VLOOKUP($A39,'BASE MATERIAL'!$A:$D,3)) | G39: =IF($A39=0,"",VLOOKUP($A39,'BASE MATERIAL'!$A:$D,4)) | H39: =IF($A39=0,"",ROUND(F39*G39,2))
B40: =IF($A40=0,"",VLOOKUP($A40,'BASE MATERIAL'!$A:$D,2)) | E40: =IF($A40=0,"",VLOOKUP($A40,'BASE MATERIAL'!$A:$D,3)) | G40: =IF($A40=0,"",VLOOKUP($A40,'BASE MATERIAL'!$A:$D,4)) | H40: =IF($A40=0,"",ROUND(F40*G40,2))
B41: =IF($A41=0,"",VLOOKUP($A41,'BASE MATERIAL'!$A:$D,2)) | E41: =IF($A41=0,"",VLOOKUP($A41,'BASE MATERIAL'!$A:$D,3)) | G41: =IF($A41=0,"",VLOOKUP($A41,'BASE MATERIAL'!$A:$D,4)) | H41: =IF($A41=0,"",ROUND(F41*G41,2))
...

Sheet 1.2
B1: NOMBRE DEL PROPONENTE: | D1: ='1.1'!$D$1 -> ESPOL | H1: FORM. #3 | L1: =A5 -> 1 | M1: =C6 -> Limpieza general de la obra | N1: =H5 -> SEMANA | O1: =H56 -> 51.73
B2: OBRA: | C2: ='1.1'!$C$2 -> 0 | G2: HOJA | I2: de
C3: ='1.1'!$C$3 -> 0
B4: ANALISIS DE PRECIOS UNITARIOS
A5: 1 | B5: RUBRO | C5: 1.2.1 | G5: UNIDAD: | H5: SEMANA
B6: DETALLE | C6: Limpieza general de la obra
B8: EQUIPOS
B9: DESCRIPCION | D9: CANTIDAD A | E9: TARIFA B | F9: COSTO HORA C= A*B | G9: RENDIMIENTO | H9: COSTO D=C*R
A10: 19015 | B10: =IF($A10=0,"",VLOOKUP($A10,'BASE EQUIPO'!$A:$D,2)) -> HERRAMIENTA MENOR | D10: 1 | E10: =IF($A10=0,"",VLOOKUP($A10,'BASE EQUIPO'!$A:$D,4)*H26) -> 1.5066 | F10: =IF($A10=0,"",ROUND(D10*E10,2)) -> 1.51 | G10: 1 | H10: =IF($A10=0,"",ROUND(G10*F10,2)) -> 1.51
B11: =IF($A11=0,"",VLOOKUP($A11,'BASE EQUIPO'!$A:$D,2)) | E11: =IF($A11=0,"",VLOOKUP($A11,'BASE EQUIPO'!$A:$D,4)) | F11: =IF($A11=0,"",ROUND(D11*E11,2)) | H11: =IF($A11=0,"",ROUND(G11*F11,2))
B12: =IF($A12=0,"",VLOOKUP($A12,'BASE EQUIPO'!$A:$D,2)) | E12: =IF($A12=0,"",VLOOKUP($A12,'BASE EQUIPO'!$A:$D,4)) | F12: =IF($A12=0,"",ROUND(D12*E12,2)) | H12: =IF($A12=0,"",ROUND(G12*F12,2))
B13: =IF($A13=0,"",VLOOKUP($A13,'BASE EQUIPO'!$A:$D,2)) | E13: =IF($A13=0,"",VLOOKUP($A13,'BASE EQUIPO'!$A:$D,4)) | F13: =IF($A13=0,"",ROUND(D13*E13,2)) | H13: =IF($A13=0,"",ROUND(G13*F13,2))
B14: =IF($A14=0,"",VLOOKUP($A14,'BASE EQUIPO'!$A:$D,2)) | E14: =IF($A14=0,"",VLOOKUP($A14,'BASE EQUIPO'!$A:$D,4)) | F14: =IF($A14=0,"",ROUND(D14*E14,2)) | H14: =IF($A14=0,"",ROUND(G14*F14,2))
B15: =IF($A15=0,"",VLOOKUP($A15,'BASE EQUIPO'!$A:$D,2)) | E15: =IF($A15=0,"",VLOOKUP($A15,'BASE EQUIPO'!$A:$D,4)) | F15: =IF($A15=0,"",ROUND(D15*E15,2)) | H15: =IF($A15=0,"",ROUND(G15*F15,2))
B16: SUBTOTAL M | H16: =ROUND(SUM(H9:H15),2) -> 1.51
B17: MANO DE OBRA
B18: DESCRIPCION (CATEG) | D18: CANTIDAD A | E18: JORNAL/HR B | F18: COSTO HORA C= A*B | G18: RENDIMIENTO | H18: COSTO D=C*R
A19: 20001 | B19: =IF($A19=0,"",VLOOKUP($A19,'BASE M-OBRA'!$A:$D,2)) -> MAESTRO | D19: 1 | E19: =IF($A19=0,"",VLOOKUP($A19,'BASE M-OBRA'!$A:$D,4)) -> 3.02 | F19: =IF($A19=0,"",ROUND(D19*E19,2)) -> 3.02 | G19: =IF($A19=0,"",ROUND(H19/F19,2)) -> 2.77 | H19: =IF($A19=0,"",ROUND(SUM(H20:H25)*'BASE M-OBRA'!$D$23,2)) -> 8.37
A20: 20002 | B20: =IF($A20=0,"",VLOOKUP($A20,'BASE M-OBRA'!$A:$D,2)) -> PEON | D20: 3 | E20: =IF($A20=0,"",VLOOKUP($A20,'BASE M-OBRA'!$A:$D,4)) -> 2.79 | F20: =IF($A20=0,"",ROUND(D20*E20,2)) -> 8.37 | G20: =5 -> 5 | H20: =IF($A20=0,"",ROUND(G20*F20,2)) -> 41.85
B21: =IF($A21=0,"",VLOOKUP($A21,'BASE M-OBRA'!$A:$D,2)) | E21: =IF($A21=0,"",VLOOKUP($A21,'BASE M-OBRA'!$A:$D,4)) | F21: =IF($A21=0,"",ROUND(D21*E21,2)) | H21: =IF($A21=0,"",ROUND(G21*F21,2))
B22: =IF($A22=0,"",VLOOKUP($A22,'BASE M-OBRA'!$A:$D,2)) | E22: =IF($A22=0,"",VLOOKUP($A22,'BASE M-OBRA'!$A:$D,4)) | F22: =IF($A22=0,"",ROUND(D22*E22,2)) | H22: =IF($A22=0,"",ROUND(G22*F22,2))
B23: =IF($A23=0,"",VLOOKUP($A23,'BASE M-OBRA'!$A:$D,2)) | E23: =IF($A23=0,"",VLOOKUP($A23,'BASE M-OBRA'!$A:$D,4)) | F23: =IF($A23=0,"",ROUND(D23*E23,2)) | H23: =IF($A23=0,"",ROUND(G23*F23,2))
B24: =IF($A24=0,"",VLOOKUP($A24,'BASE M-OBRA'!$A:$D,2)) | E24: =IF($A24=0,"",VLOOKUP($A24,'BASE M-OBRA'!$A:$D,4)) | F24: =IF($A24=0,"",ROUND(D24*E24,2)) | H24: =IF($A24=0,"",ROUND(G24*F24,2))
B25: =IF($A25=0,"",VLOOKUP($A25,'BASE M-OBRA'!$A:$D,2)) | E25: =IF($A25=0,"",VLOOKUP($A25,'BASE M-OBRA'!$A:$D,4)) | F25: =IF($A25=0,"",ROUND(D25*E25,2)) | H25: =IF($A25=0,"",ROUND(G25*F25,2))
B26: SUBTOTAL N | H26: =ROUND(SUM(H18:H25),2) -> 50.22
B27: MATERIALES
B28: DESCRIPCION | E28: UNIDAD | F28: CANTIDAD A | G28: UNITARIO B | H28: COSTO C=A*B
B29: =IF($A29=0,"",VLOOKUP($A29,'BASE MATERIAL'!$A:$D,2)) | E29: =IF($A29=0,"",VLOOKUP($A29,'BASE MATERIAL'!$A:$D,3)) | G29: =IF($A29=0,"",VLOOKUP($A29,'BASE MATERIAL'!$A:$D,4)) | H29: =IF($A29=0,"",ROUND(F29*G29,2))
B30: =IF($A30=0,"",VLOOKUP($A30,'BASE MATERIAL'!$A:$D,2)) | E30: =IF($A30=0,"",VLOOKUP($A30,'BASE MATERIAL'!$A:$D,3)) | G30: =IF($A30=0,"",VLOOKUP($A30,'BASE MATERIAL'!$A:$D,4)) | H30: =IF($A30=0,"",ROUND(F30*G30,2))
B31: =IF($A31=0,"",VLOOKUP($A31,'BASE MATERIAL'!$A:$D,2)) | E31: =IF($A31=0,"",VLOOKUP($A31,'BASE MATERIAL'!$A:$D,3)) | G31: =IF($A31=0,"",VLOOKUP($A31,'BASE MATERIAL'!$A:$D,4)) | H31: =IF($A31=0,"",ROUND(F31*G31,2))
B32: =IF($A32=0,"",VLOOKUP($A32,'BASE MATERIAL'!$A:$D,2)) | E32: =IF($A32=0,"",VLOOKUP($A32,'BASE MATERIAL'!$A:$D,3)) | G32: =IF($A32=0,"",VLOOKUP($A32,'BASE MATERIAL'!$A:$D,4)) | H32: =IF($A32=0,"",ROUND(F32*G32,2))
B33: =IF($A33=0,"",VLOOKUP($A33,'BASE MATERIAL'!$A:$D,2)) | E33: =IF($A33=0,"",VLOOKUP($A33,'BASE MATERIAL'!$A:$D,3)) | G33: =IF($A33=0,"",VLOOKUP($A33,'BASE MATERIAL'!$A:$D,4)) | H33: =IF($A33=0,"",ROUND(F33*G33,2))
B34: =IF($A34=0,"",VLOOKUP($A34,'BASE MATERIAL'!$A:$D,2)) | E34: =IF($A34=0,"",VLOOKUP($A34,'BASE MATERIAL'!$A:$D,3)) | G34: =IF($A34=0,"",VLOOKUP($A34,'BASE MATERIAL'!$A:$D,4)) | H34: =IF($A34=0,"",ROUND(F34*G34,2))
B35: =IF($A35=0,"",VLOOKUP($A35,'BASE MATERIAL'!$A:$D,2)) | E35: =IF($A35=0,"",VLOOKUP($A35,'BASE MATERIAL'!$A:$D,3)) | G35: =IF($A35=0,"",VLOOKUP($A35,'BASE MATERIAL'!$A:$D,4)) | H35: =IF($A35=0,"",ROUND(F35*G35,2))
B36: =IF($A36=0,"",VLOOKUP($A36,'BASE MATERIAL'!$A:$D,2)) | E36: =IF($A36=0,"",VLOOKUP($A36,'BASE MATERIAL'!$A:$D,3)) | G36: =IF($A36=0,"",VLOOKUP($A36,'BASE MATERIAL'!$A:$D,4)) | H36: =IF($A36=0,"",ROUND(F36*G36,2))
B37: =IF($A37=0,"",VLOOKUP($A37,'BASE MATERIAL'!$A:$D,2)) | E37: =IF($A37=0,"",VLOOKUP($A37,'BASE MATERIAL'!$A:$D,3)) | G37: =IF($A37=0,"",VLOOKUP($A37,'BASE MATERIAL'!$A:$D,4)) | H37: =IF($A37=0,"",ROUND(F37*G37,2))
B38: =IF($A38=0,"",VLOOKUP($A38,'BASE MATERIAL'!$A:$D,2)) | E38: =IF($A38=0,"",VLOOKUP($A38,'BASE MATERIAL'!$A:$D,3)) | G38: =IF($A38=0,"",VLOOKUP($A38,'BASE MATERIAL'!$A:$D,4)) | H38: =IF($A38=0,"",ROUND(F38*G38,2))
B39: =IF($A39=0,"",VLOOKUP($A39,'BASE MATERIAL'!$A:$D,2)) | E39: =IF($A39=0,"",VLOOKUP($A39,'BASE MATERIAL'!$A:$D,3)) | G39: =IF($A39=0,"",VLOOKUP($A39,'BASE MATERIAL'!$A:$D,4)) | H39: =IF($A39=0,"",ROUND(F39*G39,2))
B40: =IF($A40=0,"",VLOOKUP($A40,'BASE MATERIAL'!$A:$D,2)) | E40: =IF($A40=0,"",VLOOKUP($A40,'BASE MATERIAL'!$A:$D,3)) | G40: =IF($A40=0,"",VLOOKUP($A40,'BASE MATERIAL'!$A:$D,4)) | H40: =IF($A40=0,"",ROUND(F40*G40,2))
... B43: =IF($A43=0,"",VLOOKUP($A43,'BASE MATERIAL'!$A:$D,2)) | E43: =IF($A43=0,"",VLOOKUP($A43,'BASE MATERIAL'!$A:$D,3)) | G43: =IF($A43=0,"",VLOOKUP($A43,'BASE MATERIAL'!$A:$D,4)) | H43: =IF($A43=0,"",ROUND(F43*G43,2))
...

Sheet 1.3
B1: NOMBRE DEL PROPONENTE: | D1: ='1.1'!$D$1 -> ESPOL | H1: FORM. #3 | L1: =A5 -> 1 | M1: =C6 -> Limpieza del terreno | N1: =H5 -> m2 | O1: =H56 -> 0.56
B2: OBRA: | C2: ='1.1'!$C$2 -> 0 | G2: HOJA | I2: de
C3: ='1.1'!$C$3 -> 0
B4: ANALISIS DE PRECIOS UNITARIOS
A5: 1 | B5: RUBRO | C5: 1.3.1 | G5: UNIDAD: | H5: m2
B6: DETALLE | C6: Limpieza del terreno
B8: EQUIPOS
B9: DESCRIPCION | D9: CANTIDAD A | E9: TARIFA B | F9: COSTO HORA C= A*B | G9: RENDIMIENTO | H9: COSTO D=C*R
A10: 19015 | B10: =IF($A10=0,"",VLOOKUP($A10,'BASE EQUIPO'!$A:$D,2)) -> HERRAMIENTA MENOR | D10: 1 | E10: =IF($A10=0,"",VLOOKUP($A10,'BASE EQUIPO'!$A:$D,4)*H26) -> 0.0162 | F10: =IF($A10=0,"",ROUND(D10*E10,2)) -> 0.02 | G10: 1 | H10: =IF($A10=0,"",ROUND(G10*F10,2)) -> 0.02
B11: =IF($A11=0,"",VLOOKUP($A11,'BASE EQUIPO'!$A:$D,2)) | E11: =IF($A11=0,"",VLOOKUP($A11,'BASE EQUIPO'!$A:$D,4)) | F11: =IF($A11=0,"",ROUND(D11*E11,2)) | H11: =IF($A11=0,"",ROUND(G11*F11,2))
B12: =IF($A12=0,"",VLOOKUP($A12,'BASE EQUIPO'!$A:$D,2)) | E12: =IF($A12=0,"",VLOOKUP($A12,'BASE EQUIPO'!$A:$D,4)) | F12: =IF($A12=0,"",ROUND(D12*E12,2)) | H12: =IF($A12=0,"",ROUND(G12*F12,2))
B13: =IF($A13=0,"",VLOOKUP($A13,'BASE EQUIPO'!$A:$D,2)) | F13: =IF($A13=0,"",ROUND(D13*E13,2)) | H13: =IF($A13=0,"",ROUND(G13*F13,2))
B14: =IF($A14=0,"",VLOOKUP($A14,'BASE EQUIPO'!$A:$D,2)) | E14: =IF($A14=0,"",VLOOKUP($A14,'BASE EQUIPO'!$A:$D,4)) | F14: =IF($A14=0,"",ROUND(D14*E14,2)) | H14: =IF($A14=0,"",ROUND(G14*F14,2))
B15: =IF($A15=0,"",VLOOKUP($A15,'BASE EQUIPO'!$A:$D,2)) | E15: =IF($A15=0,"",VLOOKUP($A15,'BASE EQUIPO'!$A:$D,4)) | F15: =IF($A15=0,"",ROUND(D15*E15,2)) | H15: =IF($A15=0,"",ROUND(G15*F15,2))
B16: SUBTOTAL M | H16: =ROUND(SUM(H9:H15),2) -> 0.02 | K16: =2834.75*0.3 -> 850.425
B17: MANO DE OBRA | K17: =+K16*4.5 -> 3826.9125
B18: DESCRIPCION (CATEG) | D18: CANTIDAD A | E18: JORNAL/HR B | F18: COSTO HORA C= A*B | G18: RENDIMIENTO | H18: COSTO D=C*R
A19: 20001 | B19: =IF($A19=0,"",VLOOKUP($A19,'BASE M-OBRA'!$A:$D,2)) -> MAESTRO | D19: 1 | E19: =IF($A19=0,"",VLOOKUP($A19,'BASE M-OBRA'!$A:$D,4)) -> 3.02 | F19: =IF($A19=0,"",ROUND(D19*E19,2)) -> 3.02 | G19: =IF($A19=0,"",ROUND(H19/F19,2)) -> 0.03 | H19: =IF($A19=0,"",ROUND(SUM(H20:H25)*'BASE M-OBRA'!$D$23,2)) -> 0.09
A20: 20002 | B20: =IF($A20=0,"",VLOOKUP($A20,'BASE M-OBRA'!$A:$D,2)) -> PEON | D20: 4 | E20: =IF($A20=0,"",VLOOKUP($A20,'BASE M-OBRA'!$A:$D,4)) -> 2.79 | F20: =IF($A20=0,"",ROUND(D20*E20,2)) -> 11.16 | G20: 0.04 | H20: =IF($A20=0,"",ROUND(G20*F20,2)) -> 0.45
B21: =IF($A21=0,"",VLOOKUP($A21,'BASE M-OBRA'!$A:$D,2)) | E21: =IF($A21=0,"",VLOOKUP($A21,'BASE M-OBRA'!$A:$D,4)) | F21: =IF($A21=0,"",ROUND(D21*E21,2)) | H21: =IF($A21=0,"",ROUND(G21*F21,2))
B22: =IF($A22=0,"",VLOOKUP($A22,'BASE M-OBRA'!$A:$D,2)) | E22: =IF($A22=0,"",VLOOKUP($A22,'BASE M-OBRA'!$A:$D,4)) | F22: =IF($A22=0,"",ROUND(D22*E22,2)) | H22: =IF($A22=0,"",ROUND(G22*F22,2))
B23: =IF($A23=0,"",VLOOKUP($A23,'BASE M-OBRA'!$A:$D,2)) | E23: =IF($A23=0,"",VLOOKUP($A23,'BASE M-OBRA'!$A:$D,4)) | F23: =IF($A23=0,"",ROUND(D23*E23,2)) | H23: =IF($A23=0,"",ROUND(G23*F23,2))
B24: =IF($A24=0,"",VLOOKUP($A24,'BASE M-OBRA'!$A:$D,2)) | E24: =IF($A24=0,"",VLOOKUP($A24,'BASE M-OBRA'!$A:$D,4)) | F24: =IF($A24=0,"",ROUND(D24*E24,2)) | H24: =IF($A24=0,"",ROUND(G24*F24,2))
B25: =IF($A25=0,"",VLOOKUP($A25,'BASE M-OBRA'!$A:$D,2)) | E25: =IF($A25=0,"",VLOOKUP($A25,'BASE M-OBRA'!$A:$D,4)) | F25: =IF($A25=0,"",ROUND(D25*E25,2)) | H25: =IF($A25=0,"",ROUND(G25*F25,2))
B26: SUBTOTAL N | H26: =ROUND(SUM(H18:H25),2) -> 0.54
B27: MATERIALES
B28: DESCRIPCION | E28: UNIDAD | F28: CANTIDAD A | G28: UNITARIO B | H28: COSTO C=A*B
B29: =IF($A29=0,"",VLOOKUP($A29,'BASE MATERIAL'!$A:$D,2)) | E29: =IF($A29=0,"",VLOOKUP($A29,'BASE MATERIAL'!$A:$D,3)) | G29: =IF($A29=0,"",VLOOKUP($A29,'BASE MATERIAL'!$A:$D,4)) | H29: =IF($A29=0,"",ROUND(F29*G29,2))
B30: =IF($A30=0,"",VLOOKUP($A30,'BASE MATERIAL'!$A:$D,2)) | E30: =IF($A30=0,"",VLOOKUP($A30,'BASE MATERIAL'!$A:$D,3)) | G30: =IF($A30=0,"",VLOOKUP($A30,'BASE MATERIAL'!$A:$D,4)) | H30: =IF($A30=0,"",ROUND(F30*G30,2))
B31: =IF($A31=0,"",VLOOKUP($A31,'BASE MATERIAL'!$A:$D,2)) | E31: =IF($A31=0,"",VLOOKUP($A31,'BASE MATERIAL'!$A:$D,3)) | G31: =IF($A31=0,"",VLOOKUP($A31,'BASE MATERIAL'!$A:$D,4)) | H31: =IF($A31=0,"",ROUND(F31*G31,2))
B32: =IF($A32=0,"",VLOOKUP($A32,'BASE MATERIAL'!$A:$D,2)) | E32: =IF($A32=0,"",VLOOKUP($A32,'BASE MATERIAL'!$A:$D,3)) | G32: =IF($A32=0,"",VLOOKUP($A32,'BASE MATERIAL'!$A:$D,4)) | H32: =IF($A32=0,"",ROUND(F32*G32,2))
B33: =IF($A33=0,"",VLOOKUP($A33,'BASE MATERIAL'!$A:$D,2)) | E33: =IF($A33=0,"",VLOOKUP($A33,'BASE MATERIAL'!$A:$D,3)) | G33: =IF($A33=0,"",VLOOKUP($A33,'BASE MATERIAL'!$A:$D,4)) | H33: =IF($A33=0,"",ROUND(F33*G33,2))
B34: =IF($A34=0,"",VLOOKUP($A34,'BASE MATERIAL'!$A:$D,2)) | E34: =IF($A34=0,"",VLOOKUP($A34,'BASE MATERIAL'!$A:$D,3)) | G34: =IF($A34=0,"",VLOOKUP($A34,'BASE MATERIAL'!$A:$D,4)) | H34: =IF($A34=0,"",ROUND(F34*G34,2))
B35: =IF($A35=0,"",VLOOKUP($A35,'BASE MATERIAL'!$A:$D,2)) | E35: =IF($A35=0,"",VLOOKUP($A35,'BASE MATERIAL'!$A:$D,3)) | G35: =IF($A35=0,"",VLOOKUP($A35,'BASE MATERIAL'!$A:$D,4)) | H35: =IF($A35=0,"",ROUND(F35*G35,2))
B36: =IF($A36=0,"",VLOOKUP($A36,'BASE MATERIAL'!$A:$D,2)) | E36: =IF($A36=0,"",VLOOKUP($A36,'BASE MATERIAL'!$A:$D,3)) | G36: =IF($A36=0,"",VLOOKUP($A36,'BASE MATERIAL'!$A:$D,4)) | H36: =IF($A36=0,"",ROUND(F36*G36,2))
B37: =IF($A37=0,"",VLOOKUP($A37,'BASE MATERIAL'!$A:$D,2)) | E37: =IF($A37=0,"",VLOOKUP($A37,'BASE MATERIAL'!$A:$D,3)) | G37: =IF($A37=0,"",VLOOKUP($A37,'BASE MATERIAL'!$A:$D,4)) | H37: =IF($A37=0,"",ROUND(F37*G37,2))
B38: =IF($A38=0,"",VLOOKUP($A38,'BASE MATERIAL'!$A:$D,2)) | E38: =IF($A38=0,"",VLOOKUP($A38,'BASE MATERIAL'!$A:$D,3)) | G38: =IF($A38=0,"",VLOOKUP($A38,'BASE MATERIAL'!$A:$D,4)) | H38: =IF($A38=0,"",ROUND(F38*G38,2))
B39: =IF($A39=0,"",VLOOKUP($A39,'BASE MATERIAL'!$A:$D,2)) | E39: =IF($A39=0,"",VLOOKUP($A39,'BASE MATERIAL'!$A:$D,3)) | G39: =IF($A39=0,"",VLOOKUP($A39,'BASE MATERIAL'!$A:$D,4)) | H39: =IF($A39=0,"",ROUND(F39*G39,2))
B40: =IF($A40=0,"",VLOOKUP($A40,'BASE MATERIAL'!$A:$D,2)) | E40: =IF($A40=0,"",VLOOKUP($A40,'BASE MATERIAL'!$A:$D,3)) | G40: =IF($A40=0,"",VLOOKUP($A40,'BASE MATERIAL'!$A:$D,4)) | H40: =IF($A40=0,"",ROUND(F40*G40,2))
... B43: =IF($A43=0,"",VLOOKUP($A43,'BASE MATERIAL'!$A:$D,2)) | E43: =IF($A43=0,"",VLOOKUP($A43,'BASE MATERIAL'!$A:$D,3)) | G43: =IF($A43=0,"",VLOOKUP($A43,'BASE MATERIAL'!$A:$D,4)) | H43: =IF($A43=0,"",ROUND(F43*G43,2))
...

Sheet 1.4
B1: NOMBRE DEL PROPONENTE: | D1: ='1.1'!$D$1 -> ESPOL | H1: FORM. #3 | L1: =A5 -> 4 | M1: =C6 -> Corte de terraza (terreno rocoso) | N1: =H5 -> m3 | O1: =H56 -> 12.2
B2: OBRA: | C2: ='1.1'!$C$2 -> 0 | G2: HOJA | I2: de
C3: ='1.1'!$C$3 -> 0
B4: ANALISIS DE PRECIOS UNITARIOS
A5: 4 | B5: RUBRO | C5: 1.4.1.1 | G5: UNIDAD: | H5: m3
B6: DETALLE | C6: Corte de terraza (terreno rocoso)
B8: EQUIPOS
B9: DESCRIPCION | D9: CANTIDAD A | E9: TARIFA B | F9: COSTO HORA C= A*B | G9: RENDIMIENTO | H9: COSTO D=C*R
A10: 19015 | B10: =IF($A10=0,"",VLOOKUP($A10,'BASE EQUIPO'!$A:$D,2)) -> HERRAMIENTA MENOR | D10: 1 | E10: =IF($A10=0,"",VLOOKUP($A10,'BASE EQUIPO'!$A:$D,4)*H26)+0.06 -> 0.1509 | F10: =IF($A10=0,"",ROUND(D10*E10,2)) -> 0.15 | G10: 1 | H10: =IF($A10=0,"",ROUND(G10*F10,2)) -> 0.15
A11: 1 | B11: Martillo de aire (inc. Compresor) | D11: 2 | E11: 11 | F11: =IF($A11=0,"",ROUND(D11*E11,2)) -> 22 | G11: 0.11 | H11: =IF($A11=0,"",ROUND(G11*F11,2)) -> 2.42
A12: 19002 | B12: Retroexcavadora | D12: 2 | E12: 30 | F12: =IF($A12=0,"",ROUND(D12*E12,2)) -> 60 | G12: 0.11 | H12: =IF($A12=0,"",ROUND(G12*F12,2)) -> 6.6
B13: =IF($A13=0,"",VLOOKUP($A13,'BASE EQUIPO'!$A:$D,2)) | E13: =IF($A13=0,"",VLOOKUP($A13,'BASE EQUIPO'!$A:$D,4)) | F13: =IF($A13=0,"",ROUND(D13*E13,2)) | H13: =IF($A13=0,"",ROUND(G13*F13,2))
B14: =IF($A14=0,"",VLOOKUP($A14,'BASE EQUIPO'!$A:$D,2)) | E14: =IF($A14=0,"",VLOOKUP($A14,'BASE EQUIPO'!$A:$D,4)) | F14: =IF($A14=0,"",ROUND(D14*E14,2)) | H14: =IF($A14=0,"",ROUND(G14*F14,2))
B15: =IF($A15=0,"",VLOOKUP($A15,'BASE EQUIPO'!$A:$D,2)) | E15: =IF($A15=0,"",VLOOKUP($A15,'BASE EQUIPO'!$A:$D,4)) | F15: =IF($A15=0,"",ROUND(D15*E15,2)) | H15: =IF($A15=0,"",ROUND(G15*F15,2))
B16: SUBTOTAL M | H16: =ROUND(SUM(H9:H15),2) -> 9.17
B17: MANO DE OBRA
B18: DESCRIPCION (CATEG) | D18: CANTIDAD A | E18: JORNAL/HR B | F18: COSTO HORA C= A*B | G18: RENDIMIENTO | H18: COSTO D=C*R
A20: 20002 | B20: =IF($A20=0,"",VLOOKUP($A20,'BASE M-OBRA'!$A:$D,2)) -> PEON | D20: 6 | E20: =IF($A20=0,"",VLOOKUP($A20,'BASE M-OBRA'!$A:$D,4)) -> 2.79 | F20: =IF($A20=0,"",ROUND(D20*E20,2)) -> 16.74 | G20: 0.105 | H20: =IF($A20=0,"",ROUND(G20*F20,2)) -> 1.76
A21: 20012 | B21: =IF($A21=0,"",VLOOKUP($A21,'BASE M-OBRA'!$A:$D,2)) -> OP.EQUIPO PESADO | D21: 4 | E21: =IF($A21=0,"",VLOOKUP($A21,'BASE M-OBRA'!$A:$D,4)) -> 3.02 | F21: =IF($A21=0,"",ROUND(D21*E21,2)) -> 12.08 | G21: =+G20 -> 0.105 | H21: =IF($A21=0,"",ROUND(G21*F21,2)) -> 1.27
B22: =IF($A22=0,"",VLOOKUP($A22,'BASE M-OBRA'!$A:$D,2)) | E22: =IF($A22=0,"",VLOOKUP($A22,'BASE M-OBRA'!$A:$D,4)) | F22: =IF($A22=0,"",ROUND(D22*E22,2)) | H22: =IF($A22=0,"",ROUND(G22*F22,2))
B23: =IF($A23=0,"",VLOOKUP($A23,'BASE M-OBRA'!$A:$D,2)) | E23: =IF($A23=0,"",VLOOKUP($A23,'BASE M-OBRA'!$A:$D,4)) | F23: =IF($A23=0,"",ROUND(D23*E23,2)) | H23: =IF($A23=0,"",ROUND(G23*F23,2))
B24: =IF($A24=0,"",VLOOKUP($A24,'BASE M-OBRA'!$A:$D,2)) | E24: =IF($A24=0,"",VLOOKUP($A24,'BASE M-OBRA'!$A:$D,4)) | F24: =IF($A24=0,"",ROUND(D24*E24,2)) | H24: =IF($A24=0,"",ROUND(G24*F24,2))
B25: =IF($A25=0,"",VLOOKUP($A25,'BASE M-OBRA'!$A:$D,2)) | E25: =IF($A25=0,"",VLOOKUP($A25,'BASE M-OBRA'!$A:$D,4)) | F25: =IF($A25=0,"",ROUND(D25*E25,2)) | H25: =IF($A25=0,"",ROUND(G25*F25,2))
B26: SUBTOTAL N | H26: =ROUND(SUM(H18:H25),2) -> 3.03
B27: MATERIALES
B28: DESCRIPCION | E28: UNIDAD | F28: CANTIDAD A | G28: UNITARIO B | H28: COSTO C=A*B
B29: =IF($A29=0,"",VLOOKUP($A29,'BASE MATERIAL'!$A:$D,2)) | E29: =IF($A29=0,"",VLOOKUP($A29,'BASE MATERIAL'!$A:$D,3)) | G29: =IF($A29=0,"",VLOOKUP($A29,'BASE MATERIAL'!$A:$D,4)) | H29: =IF($A29=0,"",ROUND(F29*G29,2))
B30: =IF($A30=0,"",VLOOKUP($A30,'BASE MATERIAL'!$A:$D,2)) | E30: =IF($A30=0,"",VLOOKUP($A30,'BASE MATERIAL'!$A:$D,3)) | G30: =IF($A30=0,"",VLOOKUP($A30,'BASE MATERIAL'!$A:$D,4)) | H30: =IF($A30=0,"",ROUND(F30*G30,2))
B31: =IF($A31=0,"",VLOOKUP($A31,'BASE MATERIAL'!$A:$D,2)) | E31: =IF($A31=0,"",VLOOKUP($A31,'BASE MATERIAL'!$A:$D,3)) | G31: =IF($A31=0,"",VLOOKUP($A31,'BASE MATERIAL'!$A:$D,4)) | H31: =IF($A31=0,"",ROUND(F31*G31,2))
B32: =IF($A32=0,"",VLOOKUP($A32,'BASE MATERIAL'!$A:$D,2)) | E32: =IF($A32=0,"",VLOOKUP($A32,'BASE MATERIAL'!$A:$D,3)) | G32: =IF($A32=0,"",VLOOKUP($A32,'BASE MATERIAL'!$A:$D,4)) | H32: =IF($A32=0,"",ROUND(F32*G32,2))
B33: =IF($A33=0,"",VLOOKUP($A33,'BASE MATERIAL'!$A:$D,2)) | E33: =IF($A33=0,"",VLOOKUP($A33,'BASE MATERIAL'!$A:$D,3)) | G33: =IF($A33=0,"",VLOOKUP($A33,'BASE MATERIAL'!$A:$D,4)) | H33: =IF($A33=0,"",ROUND(F33*G33,2))
B34: =IF($A34=0,"",VLOOKUP($A34,'BASE MATERIAL'!$A:$D,2)) | E34: =IF($A34=0,"",VLOOKUP($A34,'BASE MATERIAL'!$A:$D,3)) | G34: =IF($A34=0,"",VLOOKUP($A34,'BASE MATERIAL'!$A:$D,4)) | H34: =IF($A34=0,"",ROUND(F34*G34,2))
B35: =IF($A35=0,"",VLOOKUP($A35,'BASE MATERIAL'!$A:$D,2)) | E35: =IF($A35=0,"",VLOOKUP($A35,'BASE MATERIAL'!$A:$D,3)) | G35: =IF($A35=0,"",VLOOKUP($A35,'BASE MATERIAL'!$A:$D,4)) | H35: =IF($A35=0,"",ROUND(F35*G35,2))
B36: =IF($A36=0,"",VLOOKUP($A36,'BASE MATERIAL'!$A:$D,2)) | E36: =IF($A36=0,"",VLOOKUP($A36,'BASE MATERIAL'!$A:$D,3)) | G36: =IF($A36=0,"",VLOOKUP($A36,'BASE MATERIAL'!$A:$D,4)) | H36: =IF($A36=0,"",ROUND(F36*G36,2))
B37: =IF($A37=0,"",VLOOKUP($A37,'BASE MATERIAL'!$A:$D,2)) | E37: =IF($A37=0,"",VLOOKUP($A37,'BASE MATERIAL'!$A:$D,3)) | G37: =IF($A37=0,"",VLOOKUP($A37,'BASE MATERIAL'!$A:$D,4)) | H37: =IF($A37=0,"",ROUND(F37*G37,2))
B38: =IF($A38=0,"",VLOOKUP($A38,'BASE MATERIAL'!$A:$D,2)) | E38: =IF($A38=0,"",VLOOKUP($A38,'BASE MATERIAL'!$A:$D,3)) | G38: =IF($A38=0,"",VLOOKUP($A38,'BASE MATERIAL'!$A:$D,4)) | H38: =IF($A38=0,"",ROUND(F38*G38,2))
B39: =IF($A39=0,"",VLOOKUP($A39,'BASE MATERIAL'!$A:$D,2)) | E39: =IF($A39=0,"",VLOOKUP($A39,'BASE MATERIAL'!$A:$D,3)) | G39: =IF($A39=0,"",VLOOKUP($A39,'BASE MATERIAL'!$A:$D,4)) | H39: =IF($A39=0,"",ROUND(F39*G39,2))
B40: =IF($A40=0,"",VLOOKUP($A40,'BASE MATERIAL'!$A:$D,2)) | E40: =IF($A40=0,"",VLOOKUP($A40,'BASE MATERIAL'!$A:$D,3)) | G40: =IF($A40=0,"",VLOOKUP($A40,'BASE MATERIAL'!$A:$D,4)) | H40: =IF($A40=0,"",ROUND(F40*G40,2))
... B43: =IF($A43=0,"",VLOOKUP($A43,'BASE MATERIAL'!$A:$D,2)) | E43: =IF($A43=0,"",VLOOKUP($A43,'BASE MATERIAL'!$A:$D,3)) | G43: =IF($A43=0,"",VLOOKUP($A43,'BASE MATERIAL'!$A:$D,4)) | H43: =IF($A43=0,"",ROUND(F43*G43,2))
B44: =IF($A44=0,"",VLOOKUP($A44,'BASE MATERIAL'!$A:$D,2)) | E44: =IF($A44=0,"",VLOOKUP($A44,'BASE MATERIAL'!$A:$D,3)) | G44: =IF($A44=0,"",VLOOKUP($A44,'BASE MATERIAL'!$A:$D,4)) | H44: =IF($A44=0,"",ROUND(E44*F44,2))
...

Sheet 1.5
B1: NOMBRE DEL PROPONENTE: | D1: ='1.1'!$D$1 -> ESPOL | H1: FORM. #3 | L1: =A5 -> 1 | M1: =C6 -> Replantillo hormigon simple | N1: =H5 -> m3 | O1: =H56 -> 113.61
B2: OBRA: | C2: ='1.1'!$C$2 -> 0 | G2: HOJA | I2: de
C3: ='1.1'!$C$3 -> 0
B4: ANALISIS DE PRECIOS UNITARIOS
A5: 1 | B5: RUBRO | C5: 1.5.1 | G5: UNIDAD: | H5: m3
B6: DETALLE | C6: Replantillo hormigon simple
B8: EQUIPOS
B9: DESCRIPCION | D9: CANTIDAD A | E9: TARIFA B | F9: COSTO HORA C= A*B | G9: RENDIMIENTO | H9: COSTO D=C*R
A10: 19015 | B10: =IF($A10=0,"",VLOOKUP($A10,'BASE EQUIPO'!$A:$D,2)) -> HERRAMIENTA MENOR | D10: 1 | E10: =IF($A10=0,"",VLOOKUP($A10,'BASE EQUIPO'!$A:$D,4)*H26) -> 1.2522 | F10: =IF($A10=0,"",ROUND(D10*E10,2)) -> 1.25 | G10: 1 | H10: =IF($A10=0,"",ROUND(G10*F10,2)) -> 1.25
A11: 19003 | B11: =IF($A11=0,"",VLOOKUP($A11,'BASE EQUIPO'!$A:$D,2)) -> CONCRETERA | D11: 1 | E11: =IF($A11=0,"",VLOOKUP($A11,'BASE EQUIPO'!$A:$D,4)) -> 3.5 | F11: =IF($A11=0,"",ROUND(D11*E11,2)) -> 3.5 | G11: =+G20*0.5 -> 0.775 | H11: =IF($A11=0,"",ROUND(G11*F11,2)) -> 2.71
B12: =IF($A12=0,"",VLOOKUP($A12,'BASE EQUIPO'!$A:$D,2)) | E12: =IF($A12=0,"",VLOOKUP($A12,'BASE EQUIPO'!$A:$D,4)) | F12: =IF($A12=0,"",ROUND(D12*E12,2)) | H12: =IF($A12=0,"",ROUND(G12*F12,2))
B13: =IF($A13=0,"",VLOOKUP($A13,'BASE EQUIPO'!$A:$D,2)) | E13: =IF($A13=0,"",VLOOKUP($A13,'BASE EQUIPO'!$A:$D,4)) | F13: =IF($A13=0,"",ROUND(D13*E13,2)) | H13: =IF($A13=0,"",ROUND(G13*F13,2))
B14: =IF($A14=0,"",VLOOKUP($A14,'BASE EQUIPO'!$A:$D,2)) | E14: =IF($A14=0,"",VLOOKUP($A14,'BASE EQUIPO'!$A:$D,4)) | F14: =IF($A14=0,"",ROUND(D14*E14,2)) | H14: =IF($A14=0,"",ROUND(G14*F14,2))
B15: =IF($A15=0,"",VLOOKUP($A15,'BASE EQUIPO'!$A:$D,2)) | E15: =IF($A15=0,"",VLOOKUP($A15,'BASE EQUIPO'!$A:$D,4)) | F15: =IF($A15=0,"",ROUND(D15*E15,2)) | H15: =IF($A15=0,"",ROUND(G15*F15,2))
B16: SUBTOTAL M | H16: =ROUND(SUM(H9:H15),2) -> 3.96
B17: MANO DE OBRA
B18: DESCRIPCION (CATEG) | D18: CANTIDAD A | E18: JORNAL/HR B | F18: COSTO HORA C= A*B | G18: RENDIMIENTO | H18: COSTO D=C*R
A19: 20001 | B19: =IF($A19=0,"",VLOOKUP($A19,'BASE M-OBRA'!$A:$D,2)) -> MAESTRO | D19: 1 | E19: =IF($A19=0,"",VLOOKUP($A19,'BASE M-OBRA'!$A:$D,4)) -> 3.02 | F19: =IF($A19=0,"",ROUND(D19*E19,2)) -> 3.02 | G19: =IF($A19=0,"",ROUND(H19/F19,2)) -> 2.3 | H19: =IF($A19=0,"",ROUND(SUM(H20:H25)*'BASE M-OBRA'!$D$23,2)) -> 6.96
A20: 20002 | B20: =IF($A20=0,"",VLOOKUP($A20,'BASE M-OBRA'!$A:$D,2)) -> PEON | D20: 4 | E20: =IF($A20=0,"",VLOOKUP($A20,'BASE M-OBRA'!$A:$D,4)) -> 2.79 | F20: =IF($A20=0,"",ROUND(D20*E20,2)) -> 11.16 | G20: 1.55 | H20: =IF($A20=0,"",ROUND(G20*F20,2)) -> 17.3
A21: 20003 | B21: =IF($A21=0,"",VLOOKUP($A21,'BASE M-OBRA'!$A:$D,2)) -> ALBAÑIL | D21: 2 | E21: =IF($A21=0,"",VLOOKUP($A21,'BASE M-OBRA'!$A:$D,4)) -> 2.82 | F21: =IF($A21=0,"",ROUND(D21*E21,2)) -> 5.64 | G21: =+G20 -> 1.55 | H21: =IF($A21=0,"",ROUND(G21*F21,2)) -> 8.74
A22: 20004 | B22: =IF($A22=0,"",VLOOKUP($A22,'BASE M-OBRA'!$A:$D,2)) -> CARPINTERO | D22: 2 | E22: =IF($A22=0,"",VLOOKUP($A22,'BASE M-OBRA'!$A:$D,4)) -> 2.82 | F22: =IF($A22=0,"",ROUND(D22*E22,2)) -> 5.64 | G22: =+G21 -> 1.55 | H22: =IF($A22=0,"",ROUND(G22*F22,2)) -> 8.74
B23: =IF($A23=0,"",VLOOKUP($A23,'BASE M-OBRA'!$A:$D,2)) | E23: =IF($A23=0,"",VLOOKUP($A23,'BASE M-OBRA'!$A:$D,4)) | F23: =IF($A23=0,"",ROUND(D23*E23,2)) | H23: =IF($A23=0,"",ROUND(G23*F23,2))
B24: =IF($A24=0,"",VLOOKUP($A24,'BASE M-OBRA'!$A:$D,2)) | E24: =IF($A24=0,"",VLOOKUP($A24,'BASE M-OBRA'!$A:$D,4)) | F24: =IF($A24=0,"",ROUND(D24*E24,2)) | H24: =IF($A24=0,"",ROUND(G24*F24,2))
B25: =IF($A25=0,"",VLOOKUP($A25,'BASE M-OBRA'!$A:$D,2)) | E25: =IF($A25=0,"",VLOOKUP($A25,'BASE M-OBRA'!$A:$D,4)) | F25: =IF($A25=0,"",ROUND(D25*E25,2)) | H25: =IF($A25=0,"",ROUND(G25*F25,2))
B26: SUBTOTAL N | H26: =ROUND(SUM(H18:H25),2) -> 41.74
B27: MATERIALES
B28: DESCRIPCION | E28: UNIDAD | F28: CANTIDAD A | G28: UNITARIO B | H28: COSTO C=A*B
A29: 11010 | B29: =IF($A29=0,"",VLOOKUP($A29,'BASE MATERIAL'!$A:$D,2)) -> TIRA | E29: =IF($A29=0,"",VLOOKUP($A29,'BASE MATERIAL'!$A:$D,3)) -> U | F29: 2.25 | G29: =IF($A29=0,"",VLOOKUP($A29,'BASE MATERIAL'!$A:$D,4)) -> 1.5 | H29: =IF($A29=0,"",ROUND(F29*G29,2)) -> 3.38
A30: 11007 | B30: =IF($A30=0,"",VLOOKUP($A30,'BASE MATERIAL'!$A:$D,2)) -> CLAVO 2 1/2" | E30: =IF($A30=0,"",VLOOKUP($A30,'BASE MATERIAL'!$A:$D,3)) -> KG | F30: 0.75 | G30: =IF($A30=0,"",VLOOKUP($A30,'BASE MATERIAL'!$A:$D,4)) -> 2.652 | H30: =IF($A30=0,"",ROUND(F30*G30,2)) -> 1.99
A31: 4001 | B31: =IF($A31=0,"",VLOOKUP($A31,'BASE MATERIAL'!$A:$D,2)) -> CEMENTO | E31: =IF($A31=0,"",VLOOKUP($A31,'BASE MATERIAL'!$A:$D,3)) -> SACO | F31: 6 | G31: =IF($A31=0,"",VLOOKUP($A31,'BASE MATERIAL'!$A:$D,4)) -> 7.09 | H31: =IF($A31=0,"",ROUND(F31*G31,2)) -> 42.54
A32: 5004 | B32: =IF($A32=0,"",VLOOKUP($A32,'BASE MATERIAL'!$A:$D,2)) -> ARENA | E32: =IF($A32=0,"",VLOOKUP($A32,'BASE MATERIAL'!$A:$D,3)) -> M3 | F32: =ROUND(F31*0.032*3,2) -> 0.58 | G32: =IF($A32=0,"",VLOOKUP($A32,'BASE MATERIAL'!$A:$D,4)) -> 12.27625 | H32: =IF($A32=0,"",ROUND(F32*G32,2)) -> 7.12
A33: 5002 | B33: =IF($A33=0,"",VLOOKUP($A33,'BASE MATERIAL'!$A:$D,2)) -> PIEDRA 3-4 | E33: =IF($A33=0,"",VLOOKUP($A33,'BASE MATERIAL'!$A:$D,3)) -> M3 | F33: =ROUND(F31*0.032*4,2) -> 0.77 | G33: =IF($A33=0,"",VLOOKUP($A33,'BASE MATERIAL'!$A:$D,4)) -> 13.75 | H33: =IF($A33=0,"",ROUND(F33*G33,2)) -> 10.59
A34: 5005 | B34: =IF($A34=0,"",VLOOKUP($A34,'BASE MATERIAL'!$A:$D,2)) -> AGUA | E34: =IF($A34=0,"",VLOOKUP($A34,'BASE MATERIAL'!$A:$D,3)) -> LT | F34: =26*F31 -> 156 | G34: =IF($A34=0,"",VLOOKUP($A34,'BASE MATERIAL'!$A:$D,4)) -> 0.002 | H34: =IF($A34=0,"",ROUND(F34*G34,2)) -> 0.31
B35: =IF($A35=0,"",VLOOKUP($A35,'BASE MATERIAL'!$A:$D,2)) | E35: =IF($A35=0,"",VLOOKUP($A35,'BASE MATERIAL'!$A:$D,3)) | G35: =IF($A35=0,"",VLOOKUP($A35,'BASE MATERIAL'!$A:$D,4)) | H35: =IF($A35=0,"",ROUND(F35*G35,2))
B36: =IF($A36=0,"",VLOOKUP($A36,'BASE MATERIAL'!$A:$D,2)) | E36: =IF($A36=0,"",VLOOKUP($A36,'BASE MATERIAL'!$A:$D,3)) | G36: =IF($A36=0,"",VLOOKUP($A36,'BASE MATERIAL'!$A:$D,4)) | H36: =IF($A36=0,"",ROUND(F36*G36,2))
B37: =IF($A37=0,"",VLOOKUP($A37,'BASE MATERIAL'!$A:$D,2)) | E37: =IF($A37=0,"",VLOOKUP($A37,'BASE MATERIAL'!$A:$D,3)) | G37: =IF($A37=0,"",VLOOKUP($A37,'BASE MATERIAL'!$A:$D,4)) | H37: =IF($A37=0,"",ROUND(F37*G37,2))
B38: =IF($A38=0,"",VLOOKUP($A38,'BASE MATERIAL'!$A:$D,2)) | E38: =IF($A38=0,"",VLOOKUP($A38,'BASE MATERIAL'!$A:$D,3)) | G38: =IF($A38=0,"",VLOOKUP($A38,'BASE MATERIAL'!$A:$D,4)) | H38: =IF($A38=0,"",ROUND(F38*G38,2))
B39: =IF($A39=0,"",VLOOKUP($A39,'BASE MATERIAL'!$A:$D,2)) | E39: =IF($A39=0,"",VLOOKUP($A39,'BASE MATERIAL'!$A:$D,3)) | G39: =IF($A39=0,"",VLOOKUP($A39,'BASE MATERIAL'!$A:$D,4)) | H39: =IF($A39=0,"",ROUND(F39*G39,2))
B40: =IF($A40=0,"",VLOOKUP($A40,'BASE MATERIAL'!$A:$D,2)) | E40: =IF($A40=0,"",VLOOKUP($A40,'BASE MATERIAL'!$A:$D,3)) | G40: =IF($A40=0,"",VLOOKUP($A40,'BASE MATERIAL'!$A:$D,4)) | H40: =IF($A40=0,"",ROUND(F40*G40,2))
B41: =IF($A41=0,"",VLOOKUP($A41,'BASE MATERIAL'!$A:$D,2)) | E41: =IF($A41=0,"",VLOOKUP($A41,'BASE MATERIAL'!$A:$D,3)) | G41: =IF($A41=0,"",VLOOKUP($A41,'BASE MATERIAL'!$A:$D,4)) | H41: =IF($A41=0,"",ROUND(F41*G41,2))
...

Sheet 1.6b
B1: NOMBRE DEL PROPONENTE: | D1: ='1.1'!$D$1 -> ESPOL | H1: FORM. #3 | L1: =#REF! -> #REF! | M1: =#REF! -> #REF! | N1: =#REF! -> #REF! | O1: =#REF! -> #REF!
B2: OBRA: | C2: ='1.1'!$C$2 -> 0 | G2: HOJA | I2: de
C3: ='1.1'!$C$3 -> 0
B4: ANALISIS DE PRECIOS UNITARIOS
A5: 2 | B5: RUBRO | C5: 1.6.1 | G5: UNIDAD: | H5: m3
B6: DETALLE | C6: Zapatas de cimentacion
B8: EQUIPOS
B9: DESCRIPCION | D9: CANTIDAD A | E9: TARIFA B | F9: COSTO HORA C= A*B | G9: RENDIMIENTO | H9: COSTO D=C*R
A10: 19015 | B10: =IF($A10=0,"",VLOOKUP($A10,'BASE EQUIPO'!$A:$D,2)) -> HERRAMIENTA MENOR | D10: 1 | E10: =IF($A10=0,"",VLOOKUP($A10,'BASE EQUIPO'!$A:$D,4)*H26) -> 2.6841 | F10: =IF($A10=0,"",ROUND(D10*E10,2)) -> 2.68 | G10: 1 | H10: =IF($A10=0,"",ROUND(G10*F10,2)) -> 2.68
A11: 19003 | B11: =IF($A11=0,"",VLOOKUP($A11,'BASE EQUIPO'!$A:$D,2)) -> CONCRETERA | D11: 1 | E11: =IF($A11=0,"",VLOOKUP($A11,'BASE EQUIPO'!$A:$D,4)) -> 3.5 | F11: =IF($A11=0,"",ROUND(D11*E11,2)) -> 3.5 | G11: =+G20*0.5 -> 0.35 | H11: =IF($A11=0,"",ROUND(G11*F11,2)) -> 1.23
A12: 19008 | B12: =IF($A12=0,"",VLOOKUP($A12,'BASE EQUIPO'!$A:$D,2)) -> VIBRADOR | D12: 1 | E12: =IF($A12=0,"",VLOOKUP($A12,'BASE EQUIPO'!$A:$D,4)) -> 2.5 | F12: =IF($A12=0,"",ROUND(D12*E12,2)) -> 2.5 | G12: =+G20*0.5 -> 0.35 | H12: =IF($A12=0,"",ROUND(G12*F12,2)) -> 0.88
B13: =IF($A13=0,"",VLOOKUP($A13,'BASE EQUIPO'!$A:$D,2)) | E13: =IF($A13=0,"",VLOOKUP($A13,'BASE EQUIPO'!$A:$D,4)) | F13: =IF($A13=0,"",ROUND(D13*E13,2)) | H13: =IF($A13=0,"",ROUND(G13*F13,2))
B14: =IF($A14=0,"",VLOOKUP($A14,'BASE EQUIPO'!$A:$D,2)) | E14: =IF($A14=0,"",VLOOKUP($A14,'BASE EQUIPO'!$A:$D,4)) | F14: =IF($A14=0,"",ROUND(D14*E14,2)) | H14: =IF($A14=0,"",ROUND(G14*F14,2))
B15: =IF($A15=0,"",VLOOKUP($A15,'BASE EQUIPO'!$A:$D,2)) | E15: =IF($A15=0,"",VLOOKUP($A15,'BASE EQUIPO'!$A:$D,4)) | F15: =IF($A15=0,"",ROUND(D15*E15,2)) | H15: =IF($A15=0,"",ROUND(G15*F15,2))
B16: SUBTOTAL M | H16: =ROUND(SUM(H9:H15),2) -> 4.79
B17: MANO DE OBRA
B18: DESCRIPCION (CATEG) | D18: CANTIDAD A | E18: JORNAL/HR B | F18: COSTO HORA C= A*B | G18: RENDIMIENTO | H18: COSTO D=C*R
A19: 20001 | B19: =IF($A19=0,"",VLOOKUP($A19,'BASE M-OBRA'!$A:$D,2)) -> MAESTRO | D19: 1 | E19: =IF($A19=0,"",VLOOKUP($A19,'BASE M-OBRA'!$A:$D,4)) -> 3.02 | F19: =IF($A19=0,"",ROUND(D19*E19,2)) -> 3.02 | G19: =IF($A19=0,"",ROUND(H19/F19,2)) -> 4.94 | H19: =IF($A19=0,"",ROUND(SUM(H20:H25)*'BASE M-OBRA'!$D$23,2)) -> 14.91
A20: 20002 | B20: =IF($A20=0,"",VLOOKUP($A20,'BASE M-OBRA'!$A:$D,2)) -> PEON | D20: 8 | E20: =IF($A20=0,"",VLOOKUP($A20,'BASE M-OBRA'!$A:$D,4)) -> 2.79 | F20: =IF($A20=0,"",ROUND(D20*E20,2)) -> 22.32 | G20: 0.7 | H20: =IF($A20=0,"",ROUND(G20*F20,2)) -> 15.62 | K20: =(8.94*0+22.37)/1.2 -> 18.641667 | L20: =H20+H21 -> 19.57
A21: 20003 | B21: =IF($A21=0,"",VLOOKUP($A21,'BASE M-OBRA'!$A:$D,2)) -> ALBAÑIL | D21: 2 | E21: =IF($A21=0,"",VLOOKUP($A21,'BASE M-OBRA'!$A:$D,4)) -> 2.82 | F21: =IF($A21=0,"",ROUND(D21*E21,2)) -> 5.64 | G21: =+G20 -> 0.7 | H21: =IF($A21=0,"",ROUND(G21*F21,2)) -> 3.95
A22: 20004 | B22: =IF($A22=0,"",VLOOKUP($A22,'BASE M-OBRA'!$A:$D,2)) -> CARPINTERO | D22: 2 | E22: =IF($A22=0,"",VLOOKUP($A22,'BASE M-OBRA'!$A:$D,4)) -> 2.82 | F22: =IF($A22=0,"",ROUND(D22*E22,2)) -> 5.64 | G22: 6 | H22: =IF($A22=0,"",ROUND(G22*F22,2)) -> 33.84 | K22: =(1.58*0+5.66)*K29/1.2 -> 33.016667
A23: 20005 | B23: =IF($A23=0,"",VLOOKUP($A23,'BASE M-OBRA'!$A:$D,2)) -> FIERRERO | D23: 2 | E23: =IF($A23=0,"",VLOOKUP($A23,'BASE M-OBRA'!$A:$D,4)) -> 2.82 | F23: =IF($A23=0,"",ROUND(D23*E23,2)) -> 5.64 | G23: 3.75 | H23: =IF($A23=0,"",ROUND(G23*F23,2)) -> 21.15 | K23: =+F38*0.3/1.2 -> 21.25
B24: =IF($A24=0,"",VLOOKUP($A24,'BASE M-OBRA'!$A:$D,2)) | E24: =IF($A24=0,"",VLOOKUP($A24,'BASE M-OBRA'!$A:$D,4)) | F24: =IF($A24=0,"",ROUND(D24*E24,2)) | H24: =IF($A24=0,"",ROUND(G24*F24,2))
B25: =IF($A25=0,"",VLOOKUP($A25,'BASE M-OBRA'!$A:$D,2)) | E25: =IF($A25=0,"",VLOOKUP($A25,'BASE M-OBRA'!$A:$D,4)) | F25: =IF($A25=0,"",ROUND(D25*E25,2)) | H25: =IF($A25=0,"",ROUND(G25*F25,2))
B26: SUBTOTAL N | H26: =ROUND(SUM(H18:H25),2) -> 89.47 | K26: =SUM(K19:K25) -> 72.908333
B27: MATERIALES
B28: DESCRIPCION | E28: UNIDAD | F28: CANTIDAD A | G28: UNITARIO B | H28: COSTO C=A*B
A29: 11008 | B29: =IF($A29=0,"",VLOOKUP($A29,'BASE MATERIAL'!$A:$D,2)) -> TABLA | E29: =IF($A29=0,"",VLOOKUP($A29,'BASE MATERIAL'!$A:$D,3)) -> U | F29: =ROUND(7*5/(4*3),2) -> 2.92 | G29: =IF($A29=0,"",VLOOKUP($A29,'BASE MATERIAL'!$A:$D,4)) -> 3.5 | H29: =IF($A29=0,"",ROUND(F29*G29,2)) -> 10.22 | K29: 7
A30: 11009 | B30: =IF($A30=0,"",VLOOKUP($A30,'BASE MATERIAL'!$A:$D,2)) -> CUARTON | E30: =IF($A30=0,"",VLOOKUP($A30,'BASE MATERIAL'!$A:$D,3)) -> U | F30: =ROUND(7*8/(4*3),2) -> 4.67 | G30: =IF($A30=0,"",VLOOKUP($A30,'BASE MATERIAL'!$A:$D,4)) -> 2.42 | H30: =IF($A30=0,"",ROUND(F30*G30,2)) -> 11.3
A31: 11007 | B31: =IF($A31=0,"",VLOOKUP($A31,'BASE MATERIAL'!$A:$D,2)) -> CLAVO 2 1/2" | E31: =IF($A31=0,"",VLOOKUP($A31,'BASE MATERIAL'!$A:$D,3)) -> KG | F31: =ROUND(7*56/(178*1.5),2) -> 1.47 | G31: =IF($A31=0,"",VLOOKUP($A31,'BASE MATERIAL'!$A:$D,4)) -> 2.652 | H31: =IF($A31=0,"",ROUND(F31*G31,2)) -> 3.9
A32: 11010 | B32: =IF($A32=0,"",VLOOKUP($A32,'BASE MATERIAL'!$A:$D,2)) -> TIRA | E32: =IF($A32=0,"",VLOOKUP($A32,'BASE MATERIAL'!$A:$D,3)) -> U | F32: =ROUND(7*4/(4*3),2) -> 2.33 | G32: =IF($A32=0,"",VLOOKUP($A32,'BASE MATERIAL'!$A:$D,4)) -> 1.5 | H32: =IF($A32=0,"",ROUND(F32*G32,2)) -> 3.5
A33: 4001 | B33: =IF($A33=0,"",VLOOKUP($A33,'BASE MATERIAL'!$A:$D,2)) -> CEMENTO | E33: =IF($A33=0,"",VLOOKUP($A33,'BASE MATERIAL'!$A:$D,3)) -> SACO | F33: =7*1.03 -> 7.21 | G33: =IF($A33=0,"",VLOOKUP($A33,'BASE MATERIAL'!$A:$D,4)) -> 7.09 | H33: =IF($A33=0,"",ROUND(F33*G33,2)) -> 51.12
A34: 5004 | B34: =IF($A34=0,"",VLOOKUP($A34,'BASE MATERIAL'!$A:$D,2)) -> ARENA | E34: =IF($A34=0,"",VLOOKUP($A34,'BASE MATERIAL'!$A:$D,3)) -> M3 | F34: =ROUND(F33*0.032*2,2) -> 0.46 | G34: =IF($A34=0,"",VLOOKUP($A34,'BASE MATERIAL'!$A:$D,4)) -> 12.27625 | H34: =IF($A34=0,"",ROUND(F34*G34,2)) -> 5.65
A35: 5002 | B35: =IF($A35=0,"",VLOOKUP($A35,'BASE MATERIAL'!$A:$D,2)) -> PIEDRA 3-4 | E35: =IF($A35=0,"",VLOOKUP($A35,'BASE MATERIAL'!$A:$D,3)) -> M3 | F35: =ROUND(F33*0.032*3,2) -> 0.69 | G35: =IF($A35=0,"",VLOOKUP($A35,'BASE MATERIAL'!$A:$D,4)) -> 13.75 | H35: =IF($A35=0,"",ROUND(F35*G35,2)) -> 9.49
